Workbook

Sheet Chân ghế A  - Trái
C1: GO ROUTER # LỘ TRÌNH SẢN XUẤT | J1: Mã số: SX-1/BM1 Lần ban hành: 1 Ngày BH: 7/9/2026
A2: PO NUMBER: | C2: 6126 | G2: LOẠI ĐƠN HÀNG | I2: SỐ LƯỢNG | J2: HÌNH ẢNH
A3: QTY: | C3: 110
A4: TÊN BẢN VẼ: | C4: Chân ghế A - Trái | G4: SẢN XUẤT HÀNG LOẠT | I4: =C3 -> 110
A5: MÃ BẢN VẼ: | C5: KM- 967.232006L- 01
A6: CHÚ Ý:
A8: OPERATION # 01- CẮT LASER
A9: Part Number ( Mã bản vẽ ) | B9: KM-977.22006L
A10: Ngày/Tháng/Năm | L10: Thời gian Setup ( phút )
A11: SETUP | L11: 20
A12: Nhân viên Setup
A13: Ngày/Tháng/Năm | J13: Tổng cộng | L13: Thời gian gia công / sản phẩm (s) | M13: Tổng thời gian gia công dự kiến ( giờ )
A14: Thời gian gia công | L14: 100 | M14: =$I$4*L14/3600+L11/60 -> 3.3888889
A15: Hàng đạt:
A16: Hàng lỗi:
A17: Tổng số lượng sản xuất:
A18: Nhân viên SX:
A19: Nhân viên QC:
A20: OPERATION # 02 - LÀM NGUỘI
A21: =$A$9 -> Part Number ( Mã bản vẽ )
A22: =$A$10 -> Ngày/Tháng/Năm | L22: =$L$10 -> Thời gian Setup ( phút )
A23: =$A$11 -> SETUP | L23: 0
A24: =$A$12 -> Nhân viên Setup
A25: =$A$13 -> Ngày/Tháng/Năm | J25: =$J$13 -> Tổng cộng | L25: =$L$13 -> Thời gian gia công / sản phẩm (s) | M25: =$M$13 -> Tổng thời gian gia công dự kiến ( giờ )
A26: =$A$14 -> Thời gian gia công | L26: 50 | M26: =$I$4*L26/3600+L23/60 -> 1.5277778
A27: =$A$15 -> Hàng đạt:
A28: =$A$16 -> Hàng lỗi:
A29: =$A$17 -> Tổng số lượng sản xuất:
A30: =$A$18 -> Nhân viên SX:
A31: =$A$19 -> Nhân viên QC:
A32: OPERATION # 03 - XOẮN CHÂN GHẾ
A33: =$A$9 -> Part Number ( Mã bản vẽ ) | B33: KM- 967.232006L- 01
A34: =$A$10 -> Ngày/Tháng/Năm | L34: =$L$10 -> Thời gian Setup ( phút )
A35: =$A$11 -> SETUP | L35: 40
A36: =$A$12 -> Nhân viên Setup
A37: =$A$13 -> Ngày/Tháng/Năm | J37: =$J$13 -> Tổng cộng | L37: =$L$13 -> Thời gian gia công / sản phẩm (s) | M37: =$M$13 -> Tổng thời gian gia công dự kiến ( giờ )
A38: =$A$14 -> Thời gian gia công | L38: 120 | M38: =$I$4*L38/3600+L35/60 -> 4.3333333
A39: =$A$15 -> Hàng đạt:
A40: =$A$16 -> Hàng lỗi:
A41: =$A$17 -> Tổng số lượng sản xuất:
...

Sheet Chân ghế A  - Phải
C1: ='Chân ghế A - Trái'!$C$1:$I$1 -> GO ROUTER # LỘ TRÌNH SẢN XUẤT | J1: ='Chân ghế A - Trái'!J1:M1 -> Mã số: SX-1/BM1 Lần ban hành: 1 Ngày BH: 7/9/2026
A2: ='Chân ghế A - Trái'!$A$2:$B$2 -> PO NUMBER: | C2: ='Chân ghế A - Trái'!C2:F2 -> 6126 | G2: ='Chân ghế A - Trái'!$G$2:$H$3 -> LOẠI ĐƠN HÀNG | I2: ='Chân ghế A - Trái'!$I$2:$I$3 -> SỐ LƯỢNG | J2: HÌNH ẢNH
A3: ='Chân ghế A - Trái'!A3:B3 -> QTY: | C3: ='Chân ghế A - Trái'!C3:F3 -> 110
A4: ='Chân ghế A - Trái'!$A$4:$B$4 -> TÊN BẢN VẼ: | C4: Chân ghế A - Phải | G4: ='Chân ghế A - Trái'!$G$4:$H$6 -> SẢN XUẤT HÀNG LOẠT | I4: ='Chân ghế A - Trái'!I4:I6 -> 110
A5: ='Chân ghế A - Trái'!$A$5:$B$5 -> MÃ BẢN VẼ: | C5: KM- 967.232006R- 01
A6: ='Chân ghế A - Trái'!$A$6:$B$6 -> CHÚ Ý:
A8: OPERATION # 01- CẮT LASER
A9: =$A$9 -> Part Number ( Mã bản vẽ ) | B9: KM-977.22006R
A10: =$A$10 -> Ngày/Tháng/Năm | L10: ='Chân ghế A - Trái'!$L$10:$M$10 -> Thời gian Setup ( phút )
A11: =$A$11 -> SETUP | L11: =20 -> 20
A12: =$A$12 -> Nhân viên Setup
A13: =$A$13 -> Ngày/Tháng/Năm | J13: Tổng cộng | L13: ='Chân ghế A - Trái'!L13 -> Thời gian gia công / sản phẩm (s) | M13: ='Chân ghế A - Trái'!M13 -> Tổng thời gian gia công dự kiến ( giờ )
A14: =$A$14 -> Thời gian gia công | L14: 90 | M14: =$I$4*L14/3600+L11/60 -> 3.0833333
A15: =$A$15 -> Hàng đạt:
A16: =$A$16 -> Hàng lỗi:
A17: =$A$17 -> Tổng số lượng sản xuất:
A18: =$A$18 -> Nhân viên SX:
A19: =$A$19 -> Nhân viên QC:
A20: OPERATION # 02 - LÀM NGUỘI
A21: =$A$9 -> Part Number ( Mã bản vẽ )
A22: =$A$10 -> Ngày/Tháng/Năm | L22: ='Chân ghế A - Trái'!$L$10:$M$10 -> Thời gian Setup ( phút )
A23: =$A$11 -> SETUP | L23: 0
A24: =$A$12 -> Nhân viên Setup
A25: =$A$13 -> Ngày/Tháng/Năm | J25: =$J$13 -> Tổng cộng | L25: =$L$13 -> Thời gian gia công / sản phẩm (s) | M25: =$M$13 -> Tổng thời gian gia công dự kiến ( giờ )
A26: =$A$14 -> Thời gian gia công | L26: ='Chân ghế A - Trái'!L26:L31 -> 50 | M26: =$I$4*L26/3600+L23/60 -> 1.5277778
A27: =$A$15 -> Hàng đạt:
A28: =$A$16 -> Hàng lỗi:
A29: =$A$17 -> Tổng số lượng sản xuất:
A30: =$A$18 -> Nhân viên SX:
A31: =$A$19 -> Nhân viên QC:
A32: OPERATION # 03 - XOẮN CHÂN GHẾ
A33: =$A$9 -> Part Number ( Mã bản vẽ ) | B33: KM- 967.232006L- 01
A34: =$A$10 -> Ngày/Tháng/Năm | L34: ='Chân ghế A - Trái'!$L$10:$M$10 -> Thời gian Setup ( phút )
A35: =$A$11 -> SETUP | L35: 0
A36: =$A$12 -> Nhân viên Setup
A37: =$A$13 -> Ngày/Tháng/Năm | J37: =$J$13 -> Tổng cộng | L37: =$L$13 -> Thời gian gia công / sản phẩm (s) | M37: =$M$13 -> Tổng thời gian gia công dự kiến ( giờ )
A38: =$A$14 -> Thời gian gia công | L38: 120 | M38: =$I$4*L38/3600+L35/60 -> 3.6666667
A39: =$A$15 -> Hàng đạt:
A40: =$A$16 -> Hàng lỗi:
A41: =$A$17 -> Tổng số lượng sản xuất:
...

Sheet Chân ghế B
C1: ='Chân ghế A - Trái'!$C$1:$I$1 -> GO ROUTER # LỘ TRÌNH SẢN XUẤT | J1: ='Chân ghế A - Trái'!J1:M1 -> Mã số: SX-1/BM1 Lần ban hành: 1 Ngày BH: 7/9/2026
A2: ='Chân ghế A - Trái'!$A$2:$B$2 -> PO NUMBER: | C2: ='Chân ghế A - Trái'!C2:F2 -> 6126 | G2: ='Chân ghế A - Trái'!$G$2:$H$3 -> LOẠI ĐƠN HÀNG | I2: ='Chân ghế A - Trái'!$I$2:$I$3 -> SỐ LƯỢNG | J2: HÌNH ẢNH
A3: ='Chân ghế A - Trái'!A3:B3 -> QTY: | C3: ='Chân ghế A - Trái'!C3:F3 -> 110
A4: ='Chân ghế A - Trái'!$A$4:$B$4 -> TÊN BẢN VẼ: | C4: Chân ghế B | G4: ='Chân ghế A - Trái'!$G$4:$H$6 -> SẢN XUẤT HÀNG LOẠT | I4: =$C$3*2 -> 220
A5: ='Chân ghế A - Trái'!$A$5:$B$5 -> MÃ BẢN VẼ: | C5: KM-613.332006-02
A6: ='Chân ghế A - Trái'!$A$6:$B$6 -> CHÚ Ý:
A8: OPERATION # 01- CẮT LASER
A9: =$A$9 -> Part Number ( Mã bản vẽ ) | B9: KM-613.332006-02
A10: =$A$10 -> Ngày/Tháng/Năm | L10: ='Chân ghế A - Trái'!$L$10:$M$10 -> Thời gian Setup ( phút )
A11: =$A$11 -> SETUP | L11: 20
A12: =$A$12 -> Nhân viên Setup
A13: =$A$13 -> Ngày/Tháng/Năm | J13: Tổng cộng | L13: ='Chân ghế A - Trái'!L13 -> Thời gian gia công / sản phẩm (s) | M13: ='Chân ghế A - Trái'!M13 -> Tổng thời gian gia công dự kiến ( giờ )
A14: =$A$14 -> Thời gian gia công | L14: 60 | M14: =$I$4*L14/3600+L11/60 -> 4
A15: =$A$15 -> Hàng đạt:
A16: =$A$16 -> Hàng lỗi:
A17: =$A$17 -> Tổng số lượng sản xuất:
A18: =$A$18 -> Nhân viên SX:
A19: =$A$19 -> Nhân viên QC:
A20: OPERATION # 02 - LÀM NGUỘI
A21: =$A$9 -> Part Number ( Mã bản vẽ )
A22: =$A$10 -> Ngày/Tháng/Năm | L22: ='Chân ghế A - Trái'!$L$10:$M$10 -> Thời gian Setup ( phút )
A23: =$A$11 -> SETUP | L23: 0
A24: =$A$12 -> Nhân viên Setup
A25: =$A$13 -> Ngày/Tháng/Năm | J25: =$J$13 -> Tổng cộng | L25: =$L$13 -> Thời gian gia công / sản phẩm (s) | M25: =$M$13 -> Tổng thời gian gia công dự kiến ( giờ )
A26: =$A$14 -> Thời gian gia công | L26: 40 | M26: =$I$4*L26/3600+L23/60 -> 2.4444444
A27: =$A$15 -> Hàng đạt:
A28: =$A$16 -> Hàng lỗi:
A29: =$A$17 -> Tổng số lượng sản xuất:
A30: =$A$18 -> Nhân viên SX:
A31: =$A$19 -> Nhân viên QC:
A33: XÁC NHẬN CỦA GIÁM ĐỐC SẢN XUẤT

Sheet Cung nối chân ghế - Cung lớn
C1: ='Chân ghế A - Trái'!$C$1:$I$1 -> GO ROUTER # LỘ TRÌNH SẢN XUẤT | J1: ='Chân ghế A - Trái'!J1:M1 -> Mã số: SX-1/BM1 Lần ban hành: 1 Ngày BH: 7/9/2026
A2: ='Chân ghế A - Trái'!$A$2:$B$2 -> PO NUMBER: | C2: ='Chân ghế A - Trái'!C2:F2 -> 6126 | G2: ='Chân ghế A - Trái'!$G$2:$H$3 -> LOẠI ĐƠN HÀNG | I2: ='Chân ghế A - Trái'!$I$2:$I$3 -> SỐ LƯỢNG | J2: HÌNH ẢNH
A3: ='Chân ghế A - Trái'!A3:B3 -> QTY: | C3: ='Chân ghế A - Trái'!C3:F3 -> 110
A4: ='Chân ghế A - Trái'!$A$4:$B$4 -> TÊN BẢN VẼ: | C4: Cung nối chân ghế - Cung lớn | G4: ='Chân ghế A - Trái'!$G$4:$H$6 -> SẢN XUẤT HÀNG LOẠT | I4: =$C$3 -> 110
A5: ='Chân ghế A - Trái'!$A$5:$B$5 -> MÃ BẢN VẼ: | C5: KM-367170.204-03
A6: ='Chân ghế A - Trái'!$A$6:$B$6 -> CHÚ Ý:
A8: OPERATION # 01- CẮT LASER
A9: =$A$9 -> Part Number ( Mã bản vẽ ) | B9: KM-591.12004-03
A10: =$A$10 -> Ngày/Tháng/Năm | L10: ='Chân ghế A - Trái'!$L$10:$M$10 -> Thời gian Setup ( phút )
A11: =$A$11 -> SETUP | L11: 15
A12: =$A$12 -> Nhân viên Setup
A13: =$A$13 -> Ngày/Tháng/Năm | J13: Tổng cộng | L13: ='Chân ghế A - Trái'!L13 -> Thời gian gia công / sản phẩm (s) | M13: ='Chân ghế A - Trái'!M13 -> Tổng thời gian gia công dự kiến ( giờ )
A14: =$A$14 -> Thời gian gia công | L14: 60 | M14: =$I$4*L14/3600+L11/60 -> 2.0833333
A15: =$A$15 -> Hàng đạt:
A16: =$A$16 -> Hàng lỗi:
A17: =$A$17 -> Tổng số lượng sản xuất:
A18: =$A$18 -> Nhân viên SX:
A19: =$A$19 -> Nhân viên QC:
A20: OPERATION # 02- LÀM NGUỘI
A21: =$A$9 -> Part Number ( Mã bản vẽ )
A22: =$A$10 -> Ngày/Tháng/Năm | L22: ='Chân ghế A - Trái'!$L$10:$M$10 -> Thời gian Setup ( phút )
A23: =$A$11 -> SETUP | L23: 0
A24: =$A$12 -> Nhân viên Setup
A25: =$A$13 -> Ngày/Tháng/Năm | J25: Tổng cộng | L25: ='Chân ghế A - Trái'!L25 -> Thời gian gia công / sản phẩm (s) | M25: ='Chân ghế A - Trái'!M25 -> Tổng thời gian gia công dự kiến ( giờ )
A26: =$A$14 -> Thời gian gia công | L26: 40 | M26: =$I$4*L26/3600+L23/60 -> 1.2222222
A27: =$A$15 -> Hàng đạt:
A28: =$A$16 -> Hàng lỗi:
A29: =$A$17 -> Tổng số lượng sản xuất:
A30: =$A$18 -> Nhân viên SX:
A31: =$A$19 -> Nhân viên QC:
A32: OPERATION # 03- CHẤN BƯỚC 1
A33: =$A$9 -> Part Number ( Mã bản vẽ ) | B33: KM-367170.204-03
A34: =$A$10 -> Ngày/Tháng/Năm | L34: ='Chân ghế A - Trái'!$L$10:$M$10 -> Thời gian Setup ( phút )
A35: =$A$11 -> SETUP | L35: 30
A36: =$A$12 -> Nhân viên Setup
A37: =$A$13 -> Ngày/Tháng/Năm | J37: Tổng cộng | L37: ='Chân ghế A - Trái'!L37 -> Thời gian gia công / sản phẩm (s) | M37: ='Chân ghế A - Trái'!M37 -> Tổng thời gian gia công dự kiến ( giờ )
A38: =$A$14 -> Thời gian gia công | L38: 15 | M38: =$I$4*L38/3600+L35/60 -> 0.95833333
A39: =$A$15 -> Hàng đạt:
A40: =$A$16 -> Hàng lỗi:
A41: =$A$17 -> Tổng số lượng sản xuất:
...

Sheet Cung nối chân ghế - Cung nhỏ
C1: ='Chân ghế A - Trái'!$C$1:$I$1 -> GO ROUTER # LỘ TRÌNH SẢN XUẤT | J1: ='Chân ghế A - Trái'!J1:M1 -> Mã số: SX-1/BM1 Lần ban hành: 1 Ngày BH: 7/9/2026
A2: ='Chân ghế A - Trái'!$A$2:$B$2 -> PO NUMBER: | C2: ='Chân ghế A - Trái'!C2:F2 -> 6126 | G2: ='Chân ghế A - Trái'!$G$2:$H$3 -> LOẠI ĐƠN HÀNG | I2: ='Chân ghế A - Trái'!$I$2:$I$3 -> SỐ LƯỢNG | J2: HÌNH ẢNH
A3: ='Chân ghế A - Trái'!A3:B3 -> QTY: | C3: ='Chân ghế A - Trái'!C3:F3 -> 110
A4: ='Chân ghế A - Trái'!$A$4:$B$4 -> TÊN BẢN VẼ: | C4: Cung nối chân ghế - Cung nhỏ | G4: ='Chân ghế A - Trái'!$G$4:$H$6 -> SẢN XUẤT HÀNG LOẠT | I4: =$C$3 -> 110
A5: ='Chân ghế A - Trái'!$A$5:$B$5 -> MÃ BẢN VẼ: | C5: KM-349170.204-04
A6: ='Chân ghế A - Trái'!$A$6:$B$6 -> CHÚ Ý:
A8: OPERATION # 01- CẮT LASER
A9: =$A$9 -> Part Number ( Mã bản vẽ ) | B9: KM-582.472004 - 04
A10: =$A$10 -> Ngày/Tháng/Năm | L10: ='Chân ghế A - Trái'!$L$10:$M$10 -> Thời gian Setup ( phút )
A11: =$A$11 -> SETUP | L11: 15
A12: =$A$12 -> Nhân viên Setup
A13: =$A$13 -> Ngày/Tháng/Năm | J13: Tổng cộng | L13: ='Chân ghế A - Trái'!L13 -> Thời gian gia công / sản phẩm (s) | M13: ='Chân ghế A - Trái'!M13 -> Tổng thời gian gia công dự kiến ( giờ )
A14: =$A$14 -> Thời gian gia công | L14: 60 | M14: =$I$4*L14/3600+L$11/60 -> 2.0833333
A15: =$A$15 -> Hàng đạt:
A16: =$A$16 -> Hàng lỗi:
A17: =$A$17 -> Tổng số lượng sản xuất:
A18: =$A$18 -> Nhân viên SX:
A19: =$A$19 -> Nhân viên QC:
A20: OPERATION # 02- LÀM NGUỘI
A21: =$A$9 -> Part Number ( Mã bản vẽ )
A22: =$A$10 -> Ngày/Tháng/Năm | L22: ='Chân ghế A - Trái'!$L$10:$M$10 -> Thời gian Setup ( phút )
A23: =$A$11 -> SETUP | L23: 0
A24: =$A$12 -> Nhân viên Setup
A25: =$A$13 -> Ngày/Tháng/Năm | J25: Tổng cộng | L25: ='Chân ghế A - Trái'!L25 -> Thời gian gia công / sản phẩm (s) | M25: ='Chân ghế A - Trái'!M25 -> Tổng thời gian gia công dự kiến ( giờ )
A26: =$A$14 -> Thời gian gia công | L26: 40 | M26: =$I$4*L26/3600+L23/60 -> 1.2222222
A27: =$A$15 -> Hàng đạt:
A28: =$A$16 -> Hàng lỗi:
A29: =$A$17 -> Tổng số lượng sản xuất:
A30: =$A$18 -> Nhân viên SX:
A31: =$A$19 -> Nhân viên QC:
A32: OPERATION # 03- CHẤN BƯỚC 1
A33: =$A$9 -> Part Number ( Mã bản vẽ ) | B33: KM-349170.204-04
A34: =$A$10 -> Ngày/Tháng/Năm | L34: ='Chân ghế A - Trái'!$L$10:$M$10 -> Thời gian Setup ( phút )
A35: =$A$11 -> SETUP | L35: 0
A36: =$A$12 -> Nhân viên Setup
A37: =$A$13 -> Ngày/Tháng/Năm | J37: Tổng cộng | L37: ='Chân ghế A - Trái'!L37 -> Thời gian gia công / sản phẩm (s) | M37: ='Chân ghế A - Trái'!M37 -> Tổng thời gian gia công dự kiến ( giờ )
A38: =$A$14 -> Thời gian gia công | L38: 30 | M38: =$I$4*L38/3600+L35/60 -> 0.91666667
A39: =$A$15 -> Hàng đạt:
A40: =$A$16 -> Hàng lỗi:
A41: =$A$17 -> Tổng số lượng sản xuất:
...

Sheet Gân tăng cường cung ghế nhỏ
C1: ='Chân ghế A - Trái'!$C$1:$I$1 -> GO ROUTER # LỘ TRÌNH SẢN XUẤT | J1: ='Chân ghế A - Trái'!J1:M1 -> Mã số: SX-1/BM1 Lần ban hành: 1 Ngày BH: 7/9/2026
A2: ='Chân ghế A - Trái'!$A$2:$B$2 -> PO NUMBER: | C2: ='Chân ghế A - Trái'!C2:F2 -> 6126 | G2: ='Chân ghế A - Trái'!$G$2:$H$3 -> LOẠI ĐƠN HÀNG | I2: ='Chân ghế A - Trái'!$I$2:$I$3 -> SỐ LƯỢNG | J2: HÌNH ẢNH
A3: ='Chân ghế A - Trái'!A3:B3 -> QTY: | C3: ='Chân ghế A - Trái'!C3:F3 -> 110
A4: ='Chân ghế A - Trái'!$A$4:$B$4 -> TÊN BẢN VẼ: | C4: Gân tăng cường cho cung ghế nhỏ | G4: ='Chân ghế A - Trái'!$G$4:$H$6 -> SẢN XUẤT HÀNG LOẠT | I4: =$C$3 -> 110
A5: ='Chân ghế A - Trái'!$A$5:$B$5 -> MÃ BẢN VẼ: | C5: KM-341102.5-05
A6: ='Chân ghế A - Trái'!$A$6:$B$6 -> CHÚ Ý:
A8: OPERATION # 01- CẮT LASER
A9: =$A$9 -> Part Number ( Mã bản vẽ ) | B9: KM-341102.5-05
A10: =$A$10 -> Ngày/Tháng/Năm | L10: ='Chân ghế A - Trái'!$L$10:$M$10 -> Thời gian Setup ( phút )
A11: =$A$11 -> SETUP | L11: 15
A12: =$A$12 -> Nhân viên Setup
A13: =$A$13 -> Ngày/Tháng/Năm | J13: Tổng cộng | L13: ='Chân ghế A - Trái'!L13 -> Thời gian gia công / sản phẩm (s) | M13: ='Chân ghế A - Trái'!M13 -> Tổng thời gian gia công dự kiến ( giờ )
A14: =$A$14 -> Thời gian gia công | L14: 10 | M14: =$I$4*L14/3600+$L$11/60 -> 0.55555556
A15: =$A$15 -> Hàng đạt:
A16: =$A$16 -> Hàng lỗi:
A17: =$A$17 -> Tổng số lượng sản xuất:
A18: =$A$18 -> Nhân viên SX:
A19: =$A$19 -> Nhân viên QC:
A20: OPERATION # 02- LÀM NGUỘI
A21: =$A$9 -> Part Number ( Mã bản vẽ )
A22: =$A$10 -> Ngày/Tháng/Năm | L22: ='Chân ghế A - Trái'!$L$10:$M$10 -> Thời gian Setup ( phút )
A23: =$A$11 -> SETUP | L23: 0
A24: =$A$12 -> Nhân viên Setup
A25: =$A$13 -> Ngày/Tháng/Năm | J25: Tổng cộng | L25: ='Chân ghế A - Trái'!L25 -> Thời gian gia công / sản phẩm (s) | M25: ='Chân ghế A - Trái'!M25 -> Tổng thời gian gia công dự kiến ( giờ )
A26: =$A$14 -> Thời gian gia công | L26: 40 | M26: =$I$4*L26/3600+L23/60 -> 1.2222222
A27: =$A$15 -> Hàng đạt:
A28: =$A$16 -> Hàng lỗi:
A29: =$A$17 -> Tổng số lượng sản xuất:
A30: =$A$18 -> Nhân viên SX:
A31: =$A$19 -> Nhân viên QC:
A33: XÁC NHẬN CỦA GIÁM ĐỐC SẢN XUẤT

Sheet Gân tăng cường cung ghế lớn
C1: ='Chân ghế A - Trái'!$C$1:$I$1 -> GO ROUTER # LỘ TRÌNH SẢN XUẤT | J1: ='Chân ghế A - Trái'!J1:M1 -> Mã số: SX-1/BM1 Lần ban hành: 1 Ngày BH: 7/9/2026
A2: ='Chân ghế A - Trái'!$A$2:$B$2 -> PO NUMBER: | C2: ='Chân ghế A - Trái'!C2:F2 -> 6126 | G2: ='Chân ghế A - Trái'!$G$2:$H$3 -> LOẠI ĐƠN HÀNG | I2: ='Chân ghế A - Trái'!$I$2:$I$3 -> SỐ LƯỢNG | J2: HÌNH ẢNH
A3: ='Chân ghế A - Trái'!A3:B3 -> QTY: | C3: ='Chân ghế A - Trái'!C3:F3 -> 110
A4: ='Chân ghế A - Trái'!$A$4:$B$4 -> TÊN BẢN VẼ: | C4: Gân tăng cường cho cung ghế lớn | G4: ='Chân ghế A - Trái'!$G$4:$H$6 -> SẢN XUẤT HÀNG LOẠT | I4: =$C$3 -> 110
A5: ='Chân ghế A - Trái'!$A$5:$B$5 -> MÃ BẢN VẼ: | C5: KM-359102.5-06
A6: ='Chân ghế A - Trái'!$A$6:$B$6 -> CHÚ Ý:
A8: OPERATION # 01- CẮT LASER
A9: =$A$9 -> Part Number ( Mã bản vẽ ) | B9: KM-359102.5-06
A10: =$A$10 -> Ngày/Tháng/Năm | L10: ='Chân ghế A - Trái'!$L$10:$M$10 -> Thời gian Setup ( phút )
A11: =$A$11 -> SETUP | L11: 15
A12: =$A$12 -> Nhân viên Setup
A13: =$A$13 -> Ngày/Tháng/Năm | J13: Tổng cộng | L13: ='Chân ghế A - Trái'!L13 -> Thời gian gia công / sản phẩm (s) | M13: ='Chân ghế A - Trái'!M13 -> Tổng thời gian gia công dự kiến ( giờ )
A14: =$A$14 -> Thời gian gia công | L14: 15 | M14: =$I$4*L14/3600+$L$11/60 -> 0.70833333
A15: =$A$15 -> Hàng đạt:
A16: =$A$16 -> Hàng lỗi:
A17: =$A$17 -> Tổng số lượng sản xuất:
A18: =$A$18 -> Nhân viên SX:
A19: =$A$19 -> Nhân viên QC:
A20: OPERATION # 02- LÀM NGUỘI
A21: =$A$9 -> Part Number ( Mã bản vẽ )
A22: =$A$10 -> Ngày/Tháng/Năm | L22: ='Chân ghế A - Trái'!$L$10:$M$10 -> Thời gian Setup ( phút )
A23: =$A$11 -> SETUP | L23: -
A24: =$A$12 -> Nhân viên Setup
A25: =$A$13 -> Ngày/Tháng/Năm | J25: Tổng cộng | L25: ='Chân ghế A - Trái'!L25 -> Thời gian gia công / sản phẩm (s) | M25: ='Chân ghế A - Trái'!M25 -> Tổng thời gian gia công dự kiến ( giờ )
A26: =$A$14 -> Thời gian gia công | L26: 40 | M26: =$I$4*L26/3600 -> 1.2222222
A27: =$A$15 -> Hàng đạt:
A28: =$A$16 -> Hàng lỗi:
A29: =$A$17 -> Tổng số lượng sản xuất:
A30: =$A$18 -> Nhân viên SX:
A31: =$A$19 -> Nhân viên QC:
A33: XÁC NHẬN CỦA GIÁM ĐỐC SẢN XUẤT

Sheet Thanh khung ngồi - Trái
C1: ='Chân ghế A - Trái'!$C$1:$I$1 -> GO ROUTER # LỘ TRÌNH SẢN XUẤT | J1: ='Chân ghế A - Trái'!J1:M1 -> Mã số: SX-1/BM1 Lần ban hành: 1 Ngày BH: 7/9/2026
A2: ='Chân ghế A - Trái'!$A$2:$B$2 -> PO NUMBER: | C2: ='Chân ghế A - Trái'!C2:F2 -> 6126 | G2: ='Chân ghế A - Trái'!$G$2:$H$3 -> LOẠI ĐƠN HÀNG | I2: ='Chân ghế A - Trái'!$I$2:$I$3 -> SỐ LƯỢNG | J2: HÌNH ẢNH
A3: ='Chân ghế A - Trái'!A3:B3 -> QTY: | C3: ='Chân ghế A - Trái'!C3:F3 -> 110
A4: ='Chân ghế A - Trái'!$A$4:$B$4 -> TÊN BẢN VẼ: | C4: Thanh khung ngồi - Trái | G4: ='Chân ghế A - Trái'!$G$4:$H$6 -> SẢN XUẤT HÀNG LOẠT | I4: =$C$3 -> 110
A5: ='Chân ghế A - Trái'!$A$5:$B$5 -> MÃ BẢN VẼ: | C5: KM-435.82505L-07
A6: ='Chân ghế A - Trái'!$A$6:$B$6 -> CHÚ Ý:
A8: OPERATION # 01- CẮT LASER
A9: =$A$9 -> Part Number ( Mã bản vẽ ) | B9: KM-484.762505L-07
A10: =$A$10 -> Ngày/Tháng/Năm | L10: ='Chân ghế A - Trái'!$L$10:$M$10 -> Thời gian Setup ( phút )
A11: =$A$11 -> SETUP | L11: 15
A12: =$A$12 -> Nhân viên Setup
A13: =$A$13 -> Ngày/Tháng/Năm | J13: Tổng cộng | L13: ='Chân ghế A - Trái'!L13 -> Thời gian gia công / sản phẩm (s) | M13: ='Chân ghế A - Trái'!M13 -> Tổng thời gian gia công dự kiến ( giờ )
A14: =$A$14 -> Thời gian gia công | L14: 60 | M14: =$I$4*L14/3600+L$11/60 -> 2.0833333
A15: =$A$15 -> Hàng đạt:
A16: =$A$16 -> Hàng lỗi:
A17: =$A$17 -> Tổng số lượng sản xuất:
A18: =$A$18 -> Nhân viên SX:
A19: =$A$19 -> Nhân viên QC:
A20: OPERATION # 02- LÀM NGUỘI
A21: =$A$9 -> Part Number ( Mã bản vẽ )
A22: =$A$10 -> Ngày/Tháng/Năm | L22: ='Chân ghế A - Trái'!$L$10:$M$10 -> Thời gian Setup ( phút )
A23: =$A$11 -> SETUP | L23: 0
A24: =$A$12 -> Nhân viên Setup
A25: =$A$13 -> Ngày/Tháng/Năm | J25: Tổng cộng | L25: ='Chân ghế A - Trái'!L25 -> Thời gian gia công / sản phẩm (s) | M25: ='Chân ghế A - Trái'!M25 -> Tổng thời gian gia công dự kiến ( giờ )
A26: =$A$14 -> Thời gian gia công | L26: 40 | M26: =$I$4*L26/3600+L23/60 -> 1.2222222
A27: =$A$15 -> Hàng đạt:
A28: =$A$16 -> Hàng lỗi:
A29: =$A$17 -> Tổng số lượng sản xuất:
A30: =$A$18 -> Nhân viên SX:
A31: =$A$19 -> Nhân viên QC:
A32: OPERATION # 03- CHẤN BƯỚC 1 ( chấn R để uốn )
A33: =$A$9 -> Part Number ( Mã bản vẽ ) | B33: KM-435.82505-07
A34: =$A$10 -> Ngày/Tháng/Năm | L34: ='Chân ghế A - Trái'!$L$10:$M$10 -> Thời gian Setup ( phút )
A35: =$A$11 -> SETUP | L35: 30
A36: =$A$12 -> Nhân viên Setup
A37: =$A$13 -> Ngày/Tháng/Năm | J37: Tổng cộng | L37: ='Chân ghế A - Trái'!L37 -> Thời gian gia công / sản phẩm (s) | M37: ='Chân ghế A - Trái'!M37 -> Tổng thời gian gia công dự kiến ( giờ )
A38: =$A$14 -> Thời gian gia công | L38: 15 | M38: =$I$4*L38/3600+L35/60 -> 0.95833333
A39: =$A$15 -> Hàng đạt:
A40: =$A$16 -> Hàng lỗi:
A41: =$A$17 -> Tổng số lượng sản xuất:
...

Sheet Thanh khung ngồi - Phải
C1: ='Chân ghế A - Trái'!$C$1:$I$1 -> GO ROUTER # LỘ TRÌNH SẢN XUẤT | J1: ='Chân ghế A - Trái'!J1:M1 -> Mã số: SX-1/BM1 Lần ban hành: 1 Ngày BH: 7/9/2026
A2: ='Chân ghế A - Trái'!$A$2:$B$2 -> PO NUMBER: | C2: ='Chân ghế A - Trái'!C2:F2 -> 6126 | G2: ='Chân ghế A - Trái'!$G$2:$H$3 -> LOẠI ĐƠN HÀNG | I2: ='Chân ghế A - Trái'!$I$2:$I$3 -> SỐ LƯỢNG | J2: HÌNH ẢNH
A3: ='Chân ghế A - Trái'!A3:B3 -> QTY: | C3: ='Chân ghế A - Trái'!C3:F3 -> 110
A4: ='Chân ghế A - Trái'!$A$4:$B$4 -> TÊN BẢN VẼ: | C4: Thanh khung ngồi - Phải | G4: ='Chân ghế A - Trái'!$G$4:$H$6 -> SẢN XUẤT HÀNG LOẠT | I4: =$C$3 -> 110
A5: ='Chân ghế A - Trái'!$A$5:$B$5 -> MÃ BẢN VẼ: | C5: KM-435.82505R-07
A6: ='Chân ghế A - Trái'!$A$6:$B$6 -> CHÚ Ý:
A8: OPERATION # 01- CẮT LASER
A9: =$A$9 -> Part Number ( Mã bản vẽ ) | B9: KM-484.762505R-07
A10: =$A$10 -> Ngày/Tháng/Năm | L10: ='Chân ghế A - Trái'!$L$10:$M$10 -> Thời gian Setup ( phút )
A11: =$A$11 -> SETUP | L11: 15
A12: =$A$12 -> Nhân viên Setup
A13: =$A$13 -> Ngày/Tháng/Năm | J13: Tổng cộng | L13: ='Chân ghế A - Trái'!L13 -> Thời gian gia công / sản phẩm (s) | M13: ='Chân ghế A - Trái'!M13 -> Tổng thời gian gia công dự kiến ( giờ )
A14: =$A$14 -> Thời gian gia công | L14: 70 | M14: =$I$4*L14/3600+$L$11/60 -> 2.3888889
A15: =$A$15 -> Hàng đạt:
A16: =$A$16 -> Hàng lỗi:
A17: =$A$17 -> Tổng số lượng sản xuất:
A18: =$A$18 -> Nhân viên SX:
A19: =$A$19 -> Nhân viên QC:
A20: OPERATION # 02- LÀM NGUỘI
A21: =$A$9 -> Part Number ( Mã bản vẽ )
A22: =$A$10 -> Ngày/Tháng/Năm | L22: ='Chân ghế A - Trái'!$L$10:$M$10 -> Thời gian Setup ( phút )
A23: =$A$11 -> SETUP | L23: -
A24: =$A$12 -> Nhân viên Setup
A25: =$A$13 -> Ngày/Tháng/Năm | J25: Tổng cộng | L25: ='Chân ghế A - Trái'!L25 -> Thời gian gia công / sản phẩm (s) | M25: ='Chân ghế A - Trái'!M25 -> Tổng thời gian gia công dự kiến ( giờ )
A26: =$A$14 -> Thời gian gia công | L26: 40 | M26: =$I$4*L26/3600 -> 1.2222222
A27: =$A$15 -> Hàng đạt:
A28: =$A$16 -> Hàng lỗi:
A29: =$A$17 -> Tổng số lượng sản xuất:
A30: =$A$18 -> Nhân viên SX:
A31: =$A$19 -> Nhân viên QC:
A32: OPERATION # 03- CHẤN BƯỚC 1 ( chấn R để uốn )
A33: =$A$9 -> Part Number ( Mã bản vẽ ) | B33: KM-435.82505R-07
A34: =$A$10 -> Ngày/Tháng/Năm | L34: ='Chân ghế A - Trái'!$L$10:$M$10 -> Thời gian Setup ( phút )
A35: =$A$11 -> SETUP | L35: 0
A36: =$A$12 -> Nhân viên Setup
A37: =$A$13 -> Ngày/Tháng/Năm | J37: Tổng cộng | L37: ='Chân ghế A - Trái'!L37 -> Thời gian gia công / sản phẩm (s) | M37: ='Chân ghế A - Trái'!M37 -> Tổng thời gian gia công dự kiến ( giờ )
A38: =$A$14 -> Thời gian gia công | L38: 15 | M38: =$I$4*L38/3600+L35/60 -> 0.45833333
A39: =$A$15 -> Hàng đạt:
A40: =$A$16 -> Hàng lỗi:
A41: =$A$17 -> Tổng số lượng sản xuất:
...

Sheet Thanh la khung ngồi phía trước
C1: ='Chân ghế A - Trái'!$C$1:$I$1 -> GO ROUTER # LỘ TRÌNH SẢN XUẤT | J1: ='Chân ghế A - Trái'!J1:M1 -> Mã số: SX-1/BM1 Lần ban hành: 1 Ngày BH: 7/9/2026
A2: ='Chân ghế A - Trái'!$A$2:$B$2 -> PO NUMBER: | C2: ='Chân ghế A - Trái'!C2:F2 -> 6126 | G2: ='Chân ghế A - Trái'!$G$2:$H$3 -> LOẠI ĐƠN HÀNG | I2: ='Chân ghế A - Trái'!$I$2:$I$3 -> SỐ LƯỢNG | J2: HÌNH ẢNH
A3: ='Chân ghế A - Trái'!A3:B3 -> QTY: | C3: ='Chân ghế A - Trái'!C3:F3 -> 110
A4: ='Chân ghế A - Trái'!$A$4:$B$4 -> TÊN BẢN VẼ: | C4: Thanh la khung ngồi phía trước | G4: ='Chân ghế A - Trái'!$G$4:$H$6 -> SẢN XUẤT HÀNG LOẠT | I4: =$C$3 -> 110
A5: ='Chân ghế A - Trái'!$A$5:$B$5 -> MÃ BẢN VẼ: | C5: KM-3172005-08
A6: ='Chân ghế A - Trái'!$A$6:$B$6 -> CHÚ Ý:
A8: OPERATION # 01- CẮT LASER
A9: =$A$9 -> Part Number ( Mã bản vẽ ) | B9: KM-3172005-08
A10: =$A$10 -> Ngày/Tháng/Năm | L10: ='Chân ghế A - Trái'!$L$10:$M$10 -> Thời gian Setup ( phút )
A11: =$A$11 -> SETUP | L11: 15
A12: =$A$12 -> Nhân viên Setup
A13: =$A$13 -> Ngày/Tháng/Năm | J13: Tổng cộng | L13: ='Chân ghế A - Trái'!L13 -> Thời gian gia công / sản phẩm (s) | M13: ='Chân ghế A - Trái'!M13 -> Tổng thời gian gia công dự kiến ( giờ )
A14: =$A$14 -> Thời gian gia công | L14: 60 | M14: =$I$4*L14/3600+L11/60 -> 2.0833333
A15: =$A$15 -> Hàng đạt:
A16: =$A$16 -> Hàng lỗi:
A17: =$A$17 -> Tổng số lượng sản xuất:
A18: =$A$18 -> Nhân viên SX:
A19: =$A$19 -> Nhân viên QC:
A20: OPERATION # 02- CHAMFER LỖ
A21: =$A$9 -> Part Number ( Mã bản vẽ ) | B21: KM-3172005-08
A22: =$A$10 -> Ngày/Tháng/Năm | L22: ='Chân ghế A - Trái'!$L$10:$M$10 -> Thời gian Setup ( phút )
A23: =$A$11 -> SETUP | L23: 0
A24: =$A$12 -> Nhân viên Setup
A25: =$A$13 -> Ngày/Tháng/Năm | J25: Tổng cộng | L25: ='Chân ghế A - Trái'!L25 -> Thời gian gia công / sản phẩm (s) | M25: ='Chân ghế A - Trái'!M25 -> Tổng thời gian gia công dự kiến ( giờ )
A26: =$A$14 -> Thời gian gia công | L26: 50 | M26: =$I$4*L26/3600+L23/60 -> 1.5277778
A27: =$A$15 -> Hàng đạt:
A28: =$A$16 -> Hàng lỗi:
A29: =$A$17 -> Tổng số lượng sản xuất:
A30: =$A$18 -> Nhân viên SX:
A31: =$A$19 -> Nhân viên QC:
A32: OPERATION # 02- LÀM NGUỘI
A33: =$A$9 -> Part Number ( Mã bản vẽ )
A34: =$A$10 -> Ngày/Tháng/Năm | L34: ='Chân ghế A - Trái'!$L$10:$M$10 -> Thời gian Setup ( phút )
A35: =$A$11 -> SETUP | L35: -
A36: =$A$12 -> Nhân viên Setup
A37: =$A$13 -> Ngày/Tháng/Năm | J37: Tổng cộng | L37: ='Chân ghế A - Trái'!L25 -> Thời gian gia công / sản phẩm (s) | M37: ='Chân ghế A - Trái'!M25 -> Tổng thời gian gia công dự kiến ( giờ )
A38: =$A$14 -> Thời gian gia công | L38: 40 | M38: =$I$4*L38/3600 -> 1.2222222
A39: =$A$15 -> Hàng đạt:
A40: =$A$16 -> Hàng lỗi:
A41: =$A$17 -> Tổng số lượng sản xuất:
...

Sheet Thanh la khung ngồi phía sau
C1: ='Chân ghế A - Trái'!$C$1:$I$1 -> GO ROUTER # LỘ TRÌNH SẢN XUẤT | J1: ='Chân ghế A - Trái'!J1:M1 -> Mã số: SX-1/BM1 Lần ban hành: 1 Ngày BH: 7/9/2026
A2: ='Chân ghế A - Trái'!$A$2:$B$2 -> PO NUMBER: | C2: ='Chân ghế A - Trái'!C2:F2 -> 6126 | G2: ='Chân ghế A - Trái'!$G$2:$H$3 -> LOẠI ĐƠN HÀNG | I2: ='Chân ghế A - Trái'!$I$2:$I$3 -> SỐ LƯỢNG | J2: HÌNH ẢNH
A3: ='Chân ghế A - Trái'!A3:B3 -> QTY: | C3: ='Chân ghế A - Trái'!C3:F3 -> 110
A4: ='Chân ghế A - Trái'!$A$4:$B$4 -> TÊN BẢN VẼ: | C4: Thanh la khung ngồi phía sau | G4: ='Chân ghế A - Trái'!$G$4:$H$6 -> SẢN XUẤT HÀNG LOẠT | I4: =$C$3 -> 110
A5: ='Chân ghế A - Trái'!$A$5:$B$5 -> MÃ BẢN VẼ: | C5: KM-3112005-09
A6: ='Chân ghế A - Trái'!$A$6:$B$6 -> CHÚ Ý:
A8: OPERATION # 01- CẮT LASER
A9: =$A$9 -> Part Number ( Mã bản vẽ ) | B9: KM-3112005-09
A10: =$A$10 -> Ngày/Tháng/Năm | L10: ='Chân ghế A - Trái'!$L$10:$M$10 -> Thời gian Setup ( phút )
A11: =$A$11 -> SETUP | L11: 15
A12: =$A$12 -> Nhân viên Setup
A13: =$A$13 -> Ngày/Tháng/Năm | J13: Tổng cộng | L13: ='Chân ghế A - Trái'!L13 -> Thời gian gia công / sản phẩm (s) | M13: ='Chân ghế A - Trái'!M13 -> Tổng thời gian gia công dự kiến ( giờ )
A14: =$A$14 -> Thời gian gia công | L14: 60 | M14: =$I$4*L14/3600+L11/60 -> 2.0833333
A15: =$A$15 -> Hàng đạt:
A16: =$A$16 -> Hàng lỗi:
A17: =$A$17 -> Tổng số lượng sản xuất:
A18: =$A$18 -> Nhân viên SX:
A19: =$A$19 -> Nhân viên QC:
A20: OPERATION # 02- LÀM NGUỘI
A21: =$A$9 -> Part Number ( Mã bản vẽ )
A22: =$A$10 -> Ngày/Tháng/Năm | L22: ='Chân ghế A - Trái'!$L$10:$M$10 -> Thời gian Setup ( phút )
A23: =$A$11 -> SETUP | L23: 0
A24: =$A$12 -> Nhân viên Setup
A25: =$A$13 -> Ngày/Tháng/Năm | J25: Tổng cộng | L25: ='Chân ghế A - Trái'!L25 -> Thời gian gia công / sản phẩm (s) | M25: ='Chân ghế A - Trái'!M25 -> Tổng thời gian gia công dự kiến ( giờ )
A26: =$A$14 -> Thời gian gia công | L26: 40 | M26: =$I$4*L26/3600+L23/60 -> 1.2222222
A27: =$A$15 -> Hàng đạt:
A28: =$A$16 -> Hàng lỗi:
A29: =$A$17 -> Tổng số lượng sản xuất:
A30: =$A$18 -> Nhân viên SX:
A31: =$A$19 -> Nhân viên QC:
A33: XÁC NHẬN CỦA GIÁM ĐỐC SẢN XUẤT

Sheet Thanh tựa lưng ghế
C1: ='Chân ghế A - Trái'!$C$1:$I$1 -> GO ROUTER # LỘ TRÌNH SẢN XUẤT | J1: ='Chân ghế A - Trái'!J1:M1 -> Mã số: SX-1/BM1 Lần ban hành: 1 Ngày BH: 7/9/2026
A2: ='Chân ghế A - Trái'!$A$2:$B$2 -> PO NUMBER: | C2: ='Chân ghế A - Trái'!C2:F2 -> 6126 | G2: ='Chân ghế A - Trái'!$G$2:$H$3 -> LOẠI ĐƠN HÀNG | I2: ='Chân ghế A - Trái'!$I$2:$I$3 -> SỐ LƯỢNG | J2: HÌNH ẢNH
A3: ='Chân ghế A - Trái'!A3:B3 -> QTY: | C3: ='Chân ghế A - Trái'!C3:F3 -> 110
A4: ='Chân ghế A - Trái'!$A$4:$B$4 -> TÊN BẢN VẼ: | C4: Thanh tựa lưng ghế | G4: ='Chân ghế A - Trái'!$G$4:$H$6 -> SẢN XUẤT HÀNG LOẠT | I4: =$C$3 -> 110
A5: ='Chân ghế A - Trái'!$A$5:$B$5 -> MÃ BẢN VẼ: | C5: KM-3592004-10
A6: ='Chân ghế A - Trái'!$A$6:$B$6 -> CHÚ Ý:
A8: OPERATION # 01- CẮT LASER
A9: =$A$9 -> Part Number ( Mã bản vẽ ) | B9: KM-3592004-10
A10: =$A$10 -> Ngày/Tháng/Năm | L10: ='Chân ghế A - Trái'!$L$10:$M$10 -> Thời gian Setup ( phút )
A11: =$A$11 -> SETUP | L11: 15
A12: =$A$12 -> Nhân viên Setup
A13: =$A$13 -> Ngày/Tháng/Năm | J13: Tổng cộng | L13: ='Chân ghế A - Trái'!L13 -> Thời gian gia công / sản phẩm (s) | M13: ='Chân ghế A - Trái'!M13 -> Tổng thời gian gia công dự kiến ( giờ )
A14: =$A$14 -> Thời gian gia công | L14: 60 | M14: =$I$4*L14/3600+L11/60 -> 2.0833333
A15: =$A$15 -> Hàng đạt:
A16: =$A$16 -> Hàng lỗi:
A17: =$A$17 -> Tổng số lượng sản xuất:
A18: =$A$18 -> Nhân viên SX:
A19: =$A$19 -> Nhân viên QC:
A20: OPERATION # 02- CHAMFER LỖ
A21: =$A$9 -> Part Number ( Mã bản vẽ ) | B21: KM-3592004-10
A22: =$A$10 -> Ngày/Tháng/Năm | L22: ='Chân ghế A - Trái'!$L$10:$M$10 -> Thời gian Setup ( phút )
A23: =$A$11 -> SETUP | L23: 0
A24: =$A$12 -> Nhân viên Setup
A25: =$A$13 -> Ngày/Tháng/Năm | J25: Tổng cộng | L25: ='Chân ghế A - Trái'!L25 -> Thời gian gia công / sản phẩm (s) | M25: ='Chân ghế A - Trái'!M25 -> Tổng thời gian gia công dự kiến ( giờ )
A26: =$A$14 -> Thời gian gia công | L26: 30 | M26: =$I$4*L26/3600+L23/60 -> 0.91666667
A27: =$A$15 -> Hàng đạt:
A28: =$A$16 -> Hàng lỗi:
A29: =$A$17 -> Tổng số lượng sản xuất:
A30: =$A$18 -> Nhân viên SX:
A31: =$A$19 -> Nhân viên QC:
A32: OPERATION # 02- LÀM NGUỘI
A33: =$A$9 -> Part Number ( Mã bản vẽ )
A34: =$A$10 -> Ngày/Tháng/Năm | L34: ='Chân ghế A - Trái'!$L$10:$M$10 -> Thời gian Setup ( phút )
A35: =$A$11 -> SETUP | L35: 0
A36: =$A$12 -> Nhân viên Setup
A37: =$A$13 -> Ngày/Tháng/Năm | J37: Tổng cộng | L37: ='Chân ghế A - Trái'!L25 -> Thời gian gia công / sản phẩm (s) | M37: ='Chân ghế A - Trái'!M25 -> Tổng thời gian gia công dự kiến ( giờ )
A38: =$A$14 -> Thời gian gia công | L38: 40 | M38: =$I$4*L38/3600+L35/60 -> 1.2222222
A39: =$A$15 -> Hàng đạt:
A40: =$A$16 -> Hàng lỗi:
A41: =$A$17 -> Tổng số lượng sản xuất:
...

Sheet Tay ghế - Trái
C1: ='Chân ghế A - Trái'!$C$1:$I$1 -> GO ROUTER # LỘ TRÌNH SẢN XUẤT | J1: ='Chân ghế A - Trái'!J1:M1 -> Mã số: SX-1/BM1 Lần ban hành: 1 Ngày BH: 7/9/2026
A2: ='Chân ghế A - Trái'!$A$2:$B$2 -> PO NUMBER: | C2: ='Chân ghế A - Trái'!C2:F2 -> 6126 | G2: ='Chân ghế A - Trái'!$G$2:$H$3 -> LOẠI ĐƠN HÀNG | I2: ='Chân ghế A - Trái'!$I$2:$I$3 -> SỐ LƯỢNG | J2: HÌNH ẢNH
A3: ='Chân ghế A - Trái'!A3:B3 -> QTY: | C3: ='Chân ghế A - Trái'!C3:F3 -> 110
A4: ='Chân ghế A - Trái'!$A$4:$B$4 -> TÊN BẢN VẼ: | C4: Tay ghế - Trái | G4: ='Chân ghế A - Trái'!$G$4:$H$6 -> SẢN XUẤT HÀNG LOẠT | I4: =$C$3 -> 110
A5: ='Chân ghế A - Trái'!$A$5:$B$5 -> MÃ BẢN VẼ: | C5: KM-4772005L-11
A6: ='Chân ghế A - Trái'!$A$6:$B$6 -> CHÚ Ý:
A8: OPERATION # 01- CẮT LASER
A9: =$A$9 -> Part Number ( Mã bản vẽ ) | B9: KM-762.32005 - 11
A10: =$A$10 -> Ngày/Tháng/Năm | L10: ='Chân ghế A - Trái'!$L$10:$M$10 -> Thời gian Setup ( phút )
A11: =$A$11 -> SETUP | L11: 15
A12: =$A$12 -> Nhân viên Setup
A13: =$A$13 -> Ngày/Tháng/Năm | J13: Tổng cộng | L13: ='Chân ghế A - Trái'!L13 -> Thời gian gia công / sản phẩm (s) | M13: ='Chân ghế A - Trái'!M13 -> Tổng thời gian gia công dự kiến ( giờ )
A14: =$A$14 -> Thời gian gia công | L14: 70 | M14: =$I$4*L14/3600+L11/60 -> 2.3888889
A15: =$A$15 -> Hàng đạt:
A16: =$A$16 -> Hàng lỗi:
A17: =$A$17 -> Tổng số lượng sản xuất:
A18: =$A$18 -> Nhân viên SX:
A19: =$A$19 -> Nhân viên QC:
A20: OPERATION # 02- CHAMFER LỖ
A21: =$A$9 -> Part Number ( Mã bản vẽ ) | B21: KM-4772005L-11
A22: =$A$10 -> Ngày/Tháng/Năm | L22: ='Chân ghế A - Trái'!$L$10:$M$10 -> Thời gian Setup ( phút )
A23: =$A$11 -> SETUP | L23: 0
A24: =$A$12 -> Nhân viên Setup
A25: =$A$13 -> Ngày/Tháng/Năm | J25: Tổng cộng | L25: ='Chân ghế A - Trái'!L25 -> Thời gian gia công / sản phẩm (s) | M25: ='Chân ghế A - Trái'!M25 -> Tổng thời gian gia công dự kiến ( giờ )
A26: =$A$14 -> Thời gian gia công | L26: 60 | M26: =$I$4*L26/3600+L23/60 -> 1.8333333
A27: =$A$15 -> Hàng đạt:
A28: =$A$16 -> Hàng lỗi:
A29: =$A$17 -> Tổng số lượng sản xuất:
A30: =$A$18 -> Nhân viên SX:
A31: =$A$19 -> Nhân viên QC:
A32: OPERATION # 03- LÀM NGUỘI
A33: =$A$9 -> Part Number ( Mã bản vẽ )
A34: =$A$10 -> Ngày/Tháng/Năm | L34: ='Chân ghế A - Trái'!$L$10:$M$10 -> Thời gian Setup ( phút )
A35: =$A$11 -> SETUP | L35: -
A36: =$A$12 -> Nhân viên Setup
A37: =$A$13 -> Ngày/Tháng/Năm | J37: Tổng cộng | L37: ='Chân ghế A - Trái'!L37 -> Thời gian gia công / sản phẩm (s) | M37: ='Chân ghế A - Trái'!M37 -> Tổng thời gian gia công dự kiến ( giờ )
A38: =$A$14 -> Thời gian gia công | L38: 40 | M38: =$I$4*L38/3600 -> 1.2222222
A39: =$A$15 -> Hàng đạt:
A40: =$A$16 -> Hàng lỗi:
A41: =$A$17 -> Tổng số lượng sản xuất:
...

Sheet Tay ghế - Phải
C1: ='Chân ghế A - Trái'!$C$1:$I$1 -> GO ROUTER # LỘ TRÌNH SẢN XUẤT | J1: ='Chân ghế A - Trái'!J1:M1 -> Mã số: SX-1/BM1 Lần ban hành: 1 Ngày BH: 7/9/2026
A2: ='Chân ghế A - Trái'!$A$2:$B$2 -> PO NUMBER: | C2: ='Chân ghế A - Trái'!C2:F2 -> 6126 | G2: ='Chân ghế A - Trái'!$G$2:$H$3 -> LOẠI ĐƠN HÀNG | I2: ='Chân ghế A - Trái'!$I$2:$I$3 -> SỐ LƯỢNG | J2: HÌNH ẢNH
A3: ='Chân ghế A - Trái'!A3:B3 -> QTY: | C3: ='Chân ghế A - Trái'!C3:F3 -> 110
A4: ='Chân ghế A - Trái'!$A$4:$B$4 -> TÊN BẢN VẼ: | C4: Tay ghế - Phải | G4: ='Chân ghế A - Trái'!$G$4:$H$6 -> SẢN XUẤT HÀNG LOẠT | I4: =$C$3 -> 110
A5: ='Chân ghế A - Trái'!$A$5:$B$5 -> MÃ BẢN VẼ: | C5: KM-4772005R-11
A6: ='Chân ghế A - Trái'!$A$6:$B$6 -> CHÚ Ý:
A8: OPERATION # 01- CẮT LASER
A9: =$A$9 -> Part Number ( Mã bản vẽ ) | B9: KM-762.32005 - 11
A10: =$A$10 -> Ngày/Tháng/Năm | L10: ='Chân ghế A - Trái'!$L$10:$M$10 -> Thời gian Setup ( phút )
A11: =$A$11 -> SETUP | L11: 0
A12: =$A$12 -> Nhân viên Setup
A13: =$A$13 -> Ngày/Tháng/Năm | J13: Tổng cộng | L13: ='Chân ghế A - Trái'!L13 -> Thời gian gia công / sản phẩm (s) | M13: ='Chân ghế A - Trái'!M13 -> Tổng thời gian gia công dự kiến ( giờ )
A14: =$A$14 -> Thời gian gia công | L14: 70 | M14: =$I$4*L14/3600+$L$11/60 -> 2.1388889
A15: =$A$15 -> Hàng đạt:
A16: =$A$16 -> Hàng lỗi:
A17: =$A$17 -> Tổng số lượng sản xuất:
A18: =$A$18 -> Nhân viên SX:
A19: =$A$19 -> Nhân viên QC:
A20: OPERATION # 02- CHAMFER LỖ
A21: =$A$9 -> Part Number ( Mã bản vẽ ) | B21: KM-4772005R-11
A22: =$A$10 -> Ngày/Tháng/Năm | L22: ='Chân ghế A - Trái'!$L$10:$M$10 -> Thời gian Setup ( phút )
A23: =$A$11 -> SETUP | L23: -
A24: =$A$12 -> Nhân viên Setup
A25: =$A$13 -> Ngày/Tháng/Năm | J25: Tổng cộng | L25: ='Chân ghế A - Trái'!L25 -> Thời gian gia công / sản phẩm (s) | M25: ='Chân ghế A - Trái'!M25 -> Tổng thời gian gia công dự kiến ( giờ )
A26: =$A$14 -> Thời gian gia công | L26: 60 | M26: =$I$4*L26/3600 -> 1.8333333
A27: =$A$15 -> Hàng đạt:
A28: =$A$16 -> Hàng lỗi:
A29: =$A$17 -> Tổng số lượng sản xuất:
A30: =$A$18 -> Nhân viên SX:
A31: =$A$19 -> Nhân viên QC:
A32: OPERATION # 03- LÀM NGUỘI
A33: =$A$9 -> Part Number ( Mã bản vẽ )
A34: =$A$10 -> Ngày/Tháng/Năm | L34: ='Chân ghế A - Trái'!$L$10:$M$10 -> Thời gian Setup ( phút )
A35: =$A$11 -> SETUP | L35: -
A36: =$A$12 -> Nhân viên Setup
A37: =$A$13 -> Ngày/Tháng/Năm | J37: Tổng cộng | L37: ='Chân ghế A - Trái'!L37 -> Thời gian gia công / sản phẩm (s) | M37: ='Chân ghế A - Trái'!M37 -> Tổng thời gian gia công dự kiến ( giờ )
A38: =$A$14 -> Thời gian gia công | L38: 40 | M38: =$I$4*L38/3600 -> 1.2222222
A39: =$A$15 -> Hàng đạt:
A40: =$A$16 -> Hàng lỗi:
A41: =$A$17 -> Tổng số lượng sản xuất:
...

Sheet V kết nối tay ghế phía trước
C1: ='Chân ghế A - Trái'!$C$1:$I$1 -> GO ROUTER # LỘ TRÌNH SẢN XUẤT | J1: ='Chân ghế A - Trái'!J1:M1 -> Mã số: SX-1/BM1 Lần ban hành: 1 Ngày BH: 7/9/2026
A2: ='Chân ghế A - Trái'!$A$2:$B$2 -> PO NUMBER: | C2: ='Chân ghế A - Trái'!C2:F2 -> 6126 | G2: ='Chân ghế A - Trái'!$G$2:$H$3 -> LOẠI ĐƠN HÀNG | I2: ='Chân ghế A - Trái'!$I$2:$I$3 -> SỐ LƯỢNG | J2: HÌNH ẢNH
A3: ='Chân ghế A - Trái'!A3:B3 -> QTY: | C3: ='Chân ghế A - Trái'!C3:F3 -> 110
A4: ='Chân ghế A - Trái'!$A$4:$B$4 -> TÊN BẢN VẼ: | C4: V kết nối tay ghế phía trước | G4: ='Chân ghế A - Trái'!$G$4:$H$6 -> SẢN XUẤT HÀNG LOẠT | I4: =$C$3*2 -> 220
A5: ='Chân ghế A - Trái'!$A$5:$B$5 -> MÃ BẢN VẼ: | C5: KM-49.54506-12
A6: ='Chân ghế A - Trái'!$A$6:$B$6 -> CHÚ Ý:
A8: OPERATION # 01- CẮT LASER
A9: =$A$9 -> Part Number ( Mã bản vẽ ) | B9: KM-84.520-12
A10: =$A$10 -> Ngày/Tháng/Năm | L10: ='Chân ghế A - Trái'!$L$10:$M$10 -> Thời gian Setup ( phút )
A11: =$A$11 -> SETUP | L11: 15
A12: =$A$12 -> Nhân viên Setup
A13: =$A$13 -> Ngày/Tháng/Năm | J13: Tổng cộng | L13: ='Chân ghế A - Trái'!L13 -> Thời gian gia công / sản phẩm (s) | M13: ='Chân ghế A - Trái'!M13 -> Tổng thời gian gia công dự kiến ( giờ )
A14: =$A$14 -> Thời gian gia công | L14: 40 | M14: =$I$4*L14/3600+L11/60 -> 2.6944444
A15: =$A$15 -> Hàng đạt:
A16: =$A$16 -> Hàng lỗi:
A17: =$A$17 -> Tổng số lượng sản xuất:
A18: =$A$18 -> Nhân viên SX:
A19: =$A$19 -> Nhân viên QC:
A20: OPERATION # 03- LÀM NGUỘI
A21: =$A$9 -> Part Number ( Mã bản vẽ )
A22: =$A$10 -> Ngày/Tháng/Năm | L22: ='Chân ghế A - Trái'!$L$10:$M$10 -> Thời gian Setup ( phút )
A23: =$A$11 -> SETUP | L23: 0
A24: =$A$12 -> Nhân viên Setup
A25: =$A$13 -> Ngày/Tháng/Năm | J25: Tổng cộng | L25: ='Chân ghế A - Trái'!L37 -> Thời gian gia công / sản phẩm (s) | M25: ='Chân ghế A - Trái'!M37 -> Tổng thời gian gia công dự kiến ( giờ )
A26: =$A$14 -> Thời gian gia công | L26: 20 | M26: =$I$4*L26/3600+L23/60 -> 1.2222222
A27: =$A$15 -> Hàng đạt:
A28: =$A$16 -> Hàng lỗi:
A29: =$A$17 -> Tổng số lượng sản xuất:
A30: =$A$18 -> Nhân viên SX:
A31: =$A$19 -> Nhân viên QC:
A32: OPERATION # 03- CHẤN
A33: =$A$9 -> Part Number ( Mã bản vẽ ) | B33: KM-49.54506-12
A34: =$A$10 -> Ngày/Tháng/Năm | L34: ='Chân ghế A - Trái'!$L$10:$M$10 -> Thời gian Setup ( phút )
A35: =$A$11 -> SETUP | L35: 20
A36: =$A$12 -> Nhân viên Setup
A37: =$A$13 -> Ngày/Tháng/Năm | J37: Tổng cộng | L37: ='Chân ghế A - Trái'!L37 -> Thời gian gia công / sản phẩm (s) | M37: ='Chân ghế A - Trái'!M37 -> Tổng thời gian gia công dự kiến ( giờ )
A38: =$A$14 -> Thời gian gia công | L38: 20 | M38: =$I$4*L38/3600+L35/60 -> 1.5555556
A39: =$A$15 -> Hàng đạt:
A40: =$A$16 -> Hàng lỗi:
A41: =$A$17 -> Tổng số lượng sản xuất:
...

Sheet V kết nối tay ghế phía sau
C1: ='Chân ghế A - Trái'!$C$1:$I$1 -> GO ROUTER # LỘ TRÌNH SẢN XUẤT | J1: ='Chân ghế A - Trái'!J1:M1 -> Mã số: SX-1/BM1 Lần ban hành: 1 Ngày BH: 7/9/2026
A2: ='Chân ghế A - Trái'!$A$2:$B$2 -> PO NUMBER: | C2: ='Chân ghế A - Trái'!C2:F2 -> 6126 | G2: ='Chân ghế A - Trái'!$G$2:$H$3 -> LOẠI ĐƠN HÀNG | I2: ='Chân ghế A - Trái'!$I$2:$I$3 -> SỐ LƯỢNG | J2: HÌNH ẢNH
A3: ='Chân ghế A - Trái'!A3:B3 -> QTY: | C3: ='Chân ghế A - Trái'!C3:F3 -> 110
A4: ='Chân ghế A - Trái'!$A$4:$B$4 -> TÊN BẢN VẼ: | C4: V kết nối tay ghế phía sau | G4: ='Chân ghế A - Trái'!$G$4:$H$6 -> SẢN XUẤT HÀNG LOẠT | I4: =$C$3*2 -> 220
A5: ='Chân ghế A - Trái'!$A$5:$B$5 -> MÃ BẢN VẼ: | C5: KM-5344.2606-13
A6: ='Chân ghế A - Trái'!$A$6:$B$6 -> CHÚ Ý:
A8: OPERATION # 01- CẮT LASER
A9: =$A$9 -> Part Number ( Mã bản vẽ ) | B9: KM-87.572006-13
A10: =$A$10 -> Ngày/Tháng/Năm | L10: ='Chân ghế A - Trái'!$L$10:$M$10 -> Thời gian Setup ( phút )
A11: =$A$11 -> SETUP | L11: 0
A12: =$A$12 -> Nhân viên Setup
A13: =$A$13 -> Ngày/Tháng/Năm | J13: Tổng cộng | L13: ='Chân ghế A - Trái'!L13 -> Thời gian gia công / sản phẩm (s) | M13: ='Chân ghế A - Trái'!M13 -> Tổng thời gian gia công dự kiến ( giờ )
A14: =$A$14 -> Thời gian gia công | L14: 40 | M14: =$I$4*L14/3600+L11 -> 2.4444444
A15: =$A$15 -> Hàng đạt:
A16: =$A$16 -> Hàng lỗi:
A17: =$A$17 -> Tổng số lượng sản xuất:
A18: =$A$18 -> Nhân viên SX:
A19: =$A$19 -> Nhân viên QC:
A20: OPERATION # 03- LÀM NGUỘI
A21: =$A$9 -> Part Number ( Mã bản vẽ )
A22: =$A$10 -> Ngày/Tháng/Năm | L22: ='Chân ghế A - Trái'!$L$10:$M$10 -> Thời gian Setup ( phút )
A23: =$A$11 -> SETUP | L23: 0
A24: =$A$12 -> Nhân viên Setup
A25: =$A$13 -> Ngày/Tháng/Năm | J25: Tổng cộng | L25: ='Chân ghế A - Trái'!L37 -> Thời gian gia công / sản phẩm (s) | M25: ='Chân ghế A - Trái'!M37 -> Tổng thời gian gia công dự kiến ( giờ )
A26: =$A$14 -> Thời gian gia công | L26: 20 | M26: =$I$4*L26/3600+L23/60 -> 1.2222222
A27: =$A$15 -> Hàng đạt:
A28: =$A$16 -> Hàng lỗi:
A29: =$A$17 -> Tổng số lượng sản xuất:
A30: =$A$18 -> Nhân viên SX:
A31: =$A$19 -> Nhân viên QC:
A32: OPERATION # 03- CHẤN
A33: =$A$9 -> Part Number ( Mã bản vẽ ) | B33: KM-5344.2606-13
A34: =$A$10 -> Ngày/Tháng/Năm | L34: ='Chân ghế A - Trái'!$L$10:$M$10 -> Thời gian Setup ( phút )
A35: =$A$11 -> SETUP | L35: 20
A36: =$A$12 -> Nhân viên Setup
A37: =$A$13 -> Ngày/Tháng/Năm | J37: Tổng cộng | L37: ='Chân ghế A - Trái'!L37 -> Thời gian gia công / sản phẩm (s) | M37: ='Chân ghế A - Trái'!M37 -> Tổng thời gian gia công dự kiến ( giờ )
A38: =$A$14 -> Thời gian gia công | L38: 20 | M38: =$I$4*L38/3600+L35/60 -> 1.5555556
A39: =$A$15 -> Hàng đạt:
A40: =$A$16 -> Hàng lỗi:
A41: =$A$17 -> Tổng số lượng sản xuất:
...

Sheet Thanh nối tay ghế
C1: ='Chân ghế A - Trái'!$C$1:$I$1 -> GO ROUTER # LỘ TRÌNH SẢN XUẤT | J1: ='Chân ghế A - Trái'!J1:M1 -> Mã số: SX-1/BM1 Lần ban hành: 1 Ngày BH: 7/9/2026
A2: ='Chân ghế A - Trái'!$A$2:$B$2 -> PO NUMBER: | C2: ='Chân ghế A - Trái'!C2:F2 -> 6126 | G2: ='Chân ghế A - Trái'!$G$2:$H$3 -> LOẠI ĐƠN HÀNG | I2: ='Chân ghế A - Trái'!$I$2:$I$3 -> SỐ LƯỢNG | J2: HÌNH ẢNH
A3: ='Chân ghế A - Trái'!A3:B3 -> QTY: | C3: ='Chân ghế A - Trái'!C3:F3 -> 110
A4: ='Chân ghế A - Trái'!$A$4:$B$4 -> TÊN BẢN VẼ: | C4: Thanh nối tay ghế | G4: ='Chân ghế A - Trái'!$G$4:$H$6 -> SẢN XUẤT HÀNG LOẠT | I4: =$C$3*2 -> 220
A5: ='Chân ghế A - Trái'!$A$5:$B$5 -> MÃ BẢN VẼ: | C5: KM-236.82006-14
A6: ='Chân ghế A - Trái'!$A$6:$B$6 -> CHÚ Ý:
A8: OPERATION # 01- CẮT LASER
A9: =$A$9 -> Part Number ( Mã bản vẽ ) | B9: KM-236.82006-14
A10: =$A$10 -> Ngày/Tháng/Năm | L10: ='Chân ghế A - Trái'!$L$10:$M$10 -> Thời gian Setup ( phút )
A11: =$A$11 -> SETUP | L11: 15
A12: =$A$12 -> Nhân viên Setup
A13: =$A$13 -> Ngày/Tháng/Năm | J13: Tổng cộng | L13: ='Chân ghế A - Trái'!L13 -> Thời gian gia công / sản phẩm (s) | M13: ='Chân ghế A - Trái'!M13 -> Tổng thời gian gia công dự kiến ( giờ )
A14: =$A$14 -> Thời gian gia công | L14: 50 | M14: =$I$4*L14/3600+$L$11/60 -> 3.3055556
A15: =$A$15 -> Hàng đạt:
A16: =$A$16 -> Hàng lỗi:
A17: =$A$17 -> Tổng số lượng sản xuất:
A18: =$A$18 -> Nhân viên SX:
A19: =$A$19 -> Nhân viên QC:
A20: OPERATION # 03- LÀM NGUỘI
A21: =$A$9 -> Part Number ( Mã bản vẽ )
A22: =$A$10 -> Ngày/Tháng/Năm | L22: ='Chân ghế A - Trái'!$L$10:$M$10 -> Thời gian Setup ( phút )
A23: =$A$11 -> SETUP | L23: 0
A24: =$A$12 -> Nhân viên Setup
A25: =$A$13 -> Ngày/Tháng/Năm | J25: Tổng cộng | L25: ='Chân ghế A - Trái'!L37 -> Thời gian gia công / sản phẩm (s) | M25: ='Chân ghế A - Trái'!M37 -> Tổng thời gian gia công dự kiến ( giờ )
A26: =$A$14 -> Thời gian gia công | L26: 20 | M26: =$I$4*L26/3600+L23/60 -> 1.2222222
A27: =$A$15 -> Hàng đạt:
A28: =$A$16 -> Hàng lỗi:
A29: =$A$17 -> Tổng số lượng sản xuất:
A30: =$A$18 -> Nhân viên SX:
A31: =$A$19 -> Nhân viên QC:
A33: XÁC NHẬN CỦA GIÁM ĐỐC SẢN XUẤT

Sheet Thanh khớp kéo
C1: ='Chân ghế A - Trái'!$C$1:$I$1 -> GO ROUTER # LỘ TRÌNH SẢN XUẤT | J1: ='Chân ghế A - Trái'!J1:M1 -> Mã số: SX-1/BM1 Lần ban hành: 1 Ngày BH: 7/9/2026
A2: ='Chân ghế A - Trái'!$A$2:$B$2 -> PO NUMBER: | C2: ='Chân ghế A - Trái'!C2:F2 -> 6126 | G2: ='Chân ghế A - Trái'!$G$2:$H$3 -> LOẠI ĐƠN HÀNG | I2: ='Chân ghế A - Trái'!$I$2:$I$3 -> SỐ LƯỢNG | J2: HÌNH ẢNH
A3: ='Chân ghế A - Trái'!A3:B3 -> QTY: | C3: ='Chân ghế A - Trái'!C3:F3 -> 110
A4: ='Chân ghế A - Trái'!$A$4:$B$4 -> TÊN BẢN VẼ: | C4: Thanh khớp kéo | G4: ='Chân ghế A - Trái'!$G$4:$H$6 -> SẢN XUẤT HÀNG LOẠT | I4: =$C$3*2 -> 220
A5: ='Chân ghế A - Trái'!$A$5:$B$5 -> MÃ BẢN VẼ: | C5: KM-1902004-15
A6: ='Chân ghế A - Trái'!$A$6:$B$6 -> CHÚ Ý:
A8: OPERATION # 01- CẮT LASER
A9: =$A$9 -> Part Number ( Mã bản vẽ ) | B9: KM-1902004-15
A10: =$A$10 -> Ngày/Tháng/Năm | L10: ='Chân ghế A - Trái'!$L$10:$M$10 -> Thời gian Setup ( phút )
A11: =$A$11 -> SETUP | L11: 0
A12: =$A$12 -> Nhân viên Setup
A13: =$A$13 -> Ngày/Tháng/Năm | J13: Tổng cộng | L13: ='Chân ghế A - Trái'!L13 -> Thời gian gia công / sản phẩm (s) | M13: ='Chân ghế A - Trái'!M13 -> Tổng thời gian gia công dự kiến ( giờ )
A14: =$A$14 -> Thời gian gia công | L14: 40 | M14: =$I$4*L14/3600+L11/60 -> 2.4444444
A15: =$A$15 -> Hàng đạt:
A16: =$A$16 -> Hàng lỗi:
A17: =$A$17 -> Tổng số lượng sản xuất:
A18: =$A$18 -> Nhân viên SX:
A19: =$A$19 -> Nhân viên QC:
A20: OPERATION # 03- LÀM NGUỘI
A21: =$A$9 -> Part Number ( Mã bản vẽ )
A22: =$A$10 -> Ngày/Tháng/Năm | L22: ='Chân ghế A - Trái'!$L$10:$M$10 -> Thời gian Setup ( phút )
A23: =$A$11 -> SETUP | L23: 0
A24: =$A$12 -> Nhân viên Setup
A25: =$A$13 -> Ngày/Tháng/Năm | J25: Tổng cộng | L25: ='Chân ghế A - Trái'!L37 -> Thời gian gia công / sản phẩm (s) | M25: ='Chân ghế A - Trái'!M37 -> Tổng thời gian gia công dự kiến ( giờ )
A26: =$A$14 -> Thời gian gia công | L26: 20 | M26: =$I$4*L26/3600+L23/60 -> 1.2222222
A27: =$A$15 -> Hàng đạt:
A28: =$A$16 -> Hàng lỗi:
A29: =$A$17 -> Tổng số lượng sản xuất:
A30: =$A$18 -> Nhân viên SX:
A31: =$A$19 -> Nhân viên QC:
A33: XÁC NHẬN CỦA GIÁM ĐỐC SẢN XUẤT

Sheet Pat nối khớp kéo với khung ngồi
C1: ='Chân ghế A - Trái'!$C$1:$I$1 -> GO ROUTER # LỘ TRÌNH SẢN XUẤT | J1: ='Chân ghế A - Trái'!J1:M1 -> Mã số: SX-1/BM1 Lần ban hành: 1 Ngày BH: 7/9/2026
A2: ='Chân ghế A - Trái'!$A$2:$B$2 -> PO NUMBER: | C2: ='Chân ghế A - Trái'!C2:F2 -> 6126 | G2: ='Chân ghế A - Trái'!$G$2:$H$3 -> LOẠI ĐƠN HÀNG | I2: ='Chân ghế A - Trái'!$I$2:$I$3 -> SỐ LƯỢNG | J2: HÌNH ẢNH
A3: ='Chân ghế A - Trái'!A3:B3 -> QTY: | C3: ='Chân ghế A - Trái'!C3:F3 -> 110
A4: ='Chân ghế A - Trái'!$A$4:$B$4 -> TÊN BẢN VẼ: | C4: Pat nối khớp kéo với khung ngồi | G4: ='Chân ghế A - Trái'!$G$4:$H$6 -> SẢN XUẤT HÀNG LOẠT | I4: =$C$3*2 -> 220
A5: ='Chân ghế A - Trái'!$A$5:$B$5 -> MÃ BẢN VẼ: | C5: KM-33.622006-16
A6: ='Chân ghế A - Trái'!$A$6:$B$6 -> CHÚ Ý:
A8: OPERATION # 01- CẮT LASER
A9: =$A$9 -> Part Number ( Mã bản vẽ ) | B9: KM-33.622006-16
A10: =$A$10 -> Ngày/Tháng/Năm | L10: ='Chân ghế A - Trái'!$L$10:$M$10 -> Thời gian Setup ( phút )
A11: =$A$11 -> SETUP | L11: 0
A12: =$A$12 -> Nhân viên Setup
A13: =$A$13 -> Ngày/Tháng/Năm | J13: Tổng cộng | L13: ='Chân ghế A - Trái'!L13 -> Thời gian gia công / sản phẩm (s) | M13: ='Chân ghế A - Trái'!M13 -> Tổng thời gian gia công dự kiến ( giờ )
A14: =$A$14 -> Thời gian gia công | L14: 40 | M14: =$I$4*L14/3600+L11/60 -> 2.4444444
A15: =$A$15 -> Hàng đạt:
A16: =$A$16 -> Hàng lỗi:
A17: =$A$17 -> Tổng số lượng sản xuất:
A18: =$A$18 -> Nhân viên SX:
A19: =$A$19 -> Nhân viên QC:
A20: OPERATION # 03- LÀM NGUỘI
A21: =$A$9 -> Part Number ( Mã bản vẽ )
A22: =$A$10 -> Ngày/Tháng/Năm | L22: ='Chân ghế A - Trái'!$L$10:$M$10 -> Thời gian Setup ( phút )
A23: =$A$11 -> SETUP | L23: 0
A24: =$A$12 -> Nhân viên Setup
A25: =$A$13 -> Ngày/Tháng/Năm | J25: Tổng cộng | L25: ='Chân ghế A - Trái'!L37 -> Thời gian gia công / sản phẩm (s) | M25: ='Chân ghế A - Trái'!M37 -> Tổng thời gian gia công dự kiến ( giờ )
A26: =$A$14 -> Thời gian gia công | L26: 10 | M26: =$I$4*L26/3600+L23/60 -> 0.61111111
A27: =$A$15 -> Hàng đạt:
A28: =$A$16 -> Hàng lỗi:
A29: =$A$17 -> Tổng số lượng sản xuất:
A30: =$A$18 -> Nhân viên SX:
A31: =$A$19 -> Nhân viên QC:
A33: XÁC NHẬN CỦA GIÁM ĐỐC SẢN XUẤT

Sheet Pat chân ghế
C1: ='Chân ghế A - Trái'!$C$1:$I$1 -> GO ROUTER # LỘ TRÌNH SẢN XUẤT | J1: ='Chân ghế A - Trái'!J1:M1 -> Mã số: SX-1/BM1 Lần ban hành: 1 Ngày BH: 7/9/2026
A2: ='Chân ghế A - Trái'!$A$2:$B$2 -> PO NUMBER: | C2: ='Chân ghế A - Trái'!C2:F2 -> 6126 | G2: ='Chân ghế A - Trái'!$G$2:$H$3 -> LOẠI ĐƠN HÀNG | I2: ='Chân ghế A - Trái'!$I$2:$I$3 -> SỐ LƯỢNG | J2: HÌNH ẢNH
A3: ='Chân ghế A - Trái'!A3:B3 -> QTY: | C3: ='Chân ghế A - Trái'!C3:F3 -> 110
A4: ='Chân ghế A - Trái'!$A$4:$B$4 -> TÊN BẢN VẼ: | C4: Pat chân ghế | G4: ='Chân ghế A - Trái'!$G$4:$H$6 -> SẢN XUẤT HÀNG LOẠT | I4: =$C$3*4 -> 440
A5: ='Chân ghế A - Trái'!$A$5:$B$5 -> MÃ BẢN VẼ: | C5: KM-65362.5-17
A6: ='Chân ghế A - Trái'!$A$6:$B$6 -> CHÚ Ý:
A8: OPERATION # 01- CẮT LASER
A9: =$A$9 -> Part Number ( Mã bản vẽ ) | B9: KM-65362.5-17
A10: =$A$10 -> Ngày/Tháng/Năm | L10: ='Chân ghế A - Trái'!$L$10:$M$10 -> Thời gian Setup ( phút )
A11: =$A$11 -> SETUP | L11: 15
A12: =$A$12 -> Nhân viên Setup
A13: =$A$13 -> Ngày/Tháng/Năm | J13: Tổng cộng | L13: ='Chân ghế A - Trái'!L13 -> Thời gian gia công / sản phẩm (s) | M13: ='Chân ghế A - Trái'!M13 -> Tổng thời gian gia công dự kiến ( giờ )
A14: =$A$14 -> Thời gian gia công | L14: 20 | M14: =$I$4*L14/3600+L11/60 -> 2.6944444
A15: =$A$15 -> Hàng đạt:
A16: =$A$16 -> Hàng lỗi:
A17: =$A$17 -> Tổng số lượng sản xuất:
A18: =$A$18 -> Nhân viên SX:
A19: =$A$19 -> Nhân viên QC:
A20: OPERATION # 03- LÀM NGUỘI
A21: =$A$9 -> Part Number ( Mã bản vẽ )
A22: =$A$10 -> Ngày/Tháng/Năm | L22: ='Chân ghế A - Trái'!$L$10:$M$10 -> Thời gian Setup ( phút )
A23: =$A$11 -> SETUP | L23: 0
A24: =$A$12 -> Nhân viên Setup
A25: =$A$13 -> Ngày/Tháng/Năm | J25: Tổng cộng | L25: ='Chân ghế A - Trái'!L37 -> Thời gian gia công / sản phẩm (s) | M25: ='Chân ghế A - Trái'!M37 -> Tổng thời gian gia công dự kiến ( giờ )
A26: =$A$14 -> Thời gian gia công | L26: 10 | M26: =$I$4*L26/3600+L23/60 -> 1.2222222
A27: =$A$15 -> Hàng đạt:
A28: =$A$16 -> Hàng lỗi:
A29: =$A$17 -> Tổng số lượng sản xuất:
A30: =$A$18 -> Nhân viên SX:
A31: =$A$19 -> Nhân viên QC:
A33: XÁC NHẬN CỦA GIÁM ĐỐC SẢN XUẤT

Sheet Móc khóa
C1: ='Chân ghế A - Trái'!$C$1:$I$1 -> GO ROUTER # LỘ TRÌNH SẢN XUẤT | J1: ='Chân ghế A - Trái'!J1:M1 -> Mã số: SX-1/BM1 Lần ban hành: 1 Ngày BH: 7/9/2026
A2: ='Chân ghế A - Trái'!$A$2:$B$2 -> PO NUMBER: | C2: ='Chân ghế A - Trái'!C2:F2 -> 6126 | G2: ='Chân ghế A - Trái'!$G$2:$H$3 -> LOẠI ĐƠN HÀNG | I2: ='Chân ghế A - Trái'!$I$2:$I$3 -> SỐ LƯỢNG | J2: HÌNH ẢNH
A3: ='Chân ghế A - Trái'!A3:B3 -> QTY: | C3: ='Chân ghế A - Trái'!C3:F3 -> 110
A4: ='Chân ghế A - Trái'!$A$4:$B$4 -> TÊN BẢN VẼ: | C4: Móc khóa | G4: ='Chân ghế A - Trái'!$G$4:$H$6 -> SẢN XUẤT HÀNG LOẠT | I4: =$C$3 -> 110
A5: ='Chân ghế A - Trái'!$A$5:$B$5 -> MÃ BẢN VẼ: | C5: KM - 3519.712.5 - 18
A6: ='Chân ghế A - Trái'!$A$6:$B$6 -> CHÚ Ý:
A8: OPERATION # 01- CẮT LASER
A9: =$A$9 -> Part Number ( Mã bản vẽ ) | B9: KM-41.619.702-18
A10: =$A$10 -> Ngày/Tháng/Năm | L10: ='Chân ghế A - Trái'!$L$10:$M$10 -> Thời gian Setup ( phút )
A11: =$A$11 -> SETUP | L11: 15
A12: =$A$12 -> Nhân viên Setup
A13: =$A$13 -> Ngày/Tháng/Năm | J13: Tổng cộng | L13: ='Chân ghế A - Trái'!L13 -> Thời gian gia công / sản phẩm (s) | M13: ='Chân ghế A - Trái'!M13 -> Tổng thời gian gia công dự kiến ( giờ )
A14: =$A$14 -> Thời gian gia công | L14: 20 | M14: =$I$4*L14/3600+$L$11/60 -> 0.86111111
A15: =$A$15 -> Hàng đạt:
A16: =$A$16 -> Hàng lỗi:
A17: =$A$17 -> Tổng số lượng sản xuất:
A18: =$A$18 -> Nhân viên SX:
A19: =$A$19 -> Nhân viên QC:
A20: OPERATION # 03- LÀM NGUỘI
A21: =$A$9 -> Part Number ( Mã bản vẽ )
A22: =$A$10 -> Ngày/Tháng/Năm | L22: ='Chân ghế A - Trái'!$L$10:$M$10 -> Thời gian Setup ( phút )
A23: =$A$11 -> SETUP | L23: 0
A24: =$A$12 -> Nhân viên Setup
A25: =$A$13 -> Ngày/Tháng/Năm | J25: Tổng cộng | L25: ='Chân ghế A - Trái'!$L$37 -> Thời gian gia công / sản phẩm (s) | M25: ='Chân ghế A - Trái'!$M$37 -> Tổng thời gian gia công dự kiến ( giờ )
A26: =$A$14 -> Thời gian gia công | L26: 10 | M26: =$I$4*L26/3600 -> 0.30555556
A27: =$A$15 -> Hàng đạt:
A28: =$A$16 -> Hàng lỗi:
A29: =$A$17 -> Tổng số lượng sản xuất:
A30: =$A$18 -> Nhân viên SX:
A31: =$A$19 -> Nhân viên QC:
A32: OPERATION # 03- CHẤN
A33: =$A$9 -> Part Number ( Mã bản vẽ ) | B33: KM - 3519.712.5 - 18
A34: =$A$10 -> Ngày/Tháng/Năm | L34: ='Chân ghế A - Trái'!$L$10:$M$10 -> Thời gian Setup ( phút )
A35: =$A$11 -> SETUP | L35: 30
A36: =$A$12 -> Nhân viên Setup
A37: =$A$13 -> Ngày/Tháng/Năm | J37: Tổng cộng | L37: ='Chân ghế A - Trái'!$L$37 -> Thời gian gia công / sản phẩm (s) | M37: ='Chân ghế A - Trái'!$M$37 -> Tổng thời gian gia công dự kiến ( giờ )
A38: =$A$14 -> Thời gian gia công | L38: 30 | M38: =$I$4*L38/3600+L35/60 -> 1.4166667
A39: =$A$15 -> Hàng đạt:
A40: =$A$16 -> Hàng lỗi:
A41: =$A$17 -> Tổng số lượng sản xuất:
...

Sheet Thanh omega
C1: ='Chân ghế A - Trái'!$C$1:$I$1 -> GO ROUTER # LỘ TRÌNH SẢN XUẤT | J1: ='Chân ghế A - Trái'!J1:M1 -> Mã số: SX-1/BM1 Lần ban hành: 1 Ngày BH: 7/9/2026
A2: ='Chân ghế A - Trái'!$A$2:$B$2 -> PO NUMBER: | C2: ='Chân ghế A - Trái'!C2:F2 -> 6126 | G2: ='Chân ghế A - Trái'!$G$2:$H$3 -> LOẠI ĐƠN HÀNG | I2: ='Chân ghế A - Trái'!$I$2:$I$3 -> SỐ LƯỢNG | J2: HÌNH ẢNH
A3: ='Chân ghế A - Trái'!A3:B3 -> QTY: | C3: ='Chân ghế A - Trái'!C3:F3 -> 110
A4: ='Chân ghế A - Trái'!$A$4:$B$4 -> TÊN BẢN VẼ: | C4: Thanh omega | G4: ='Chân ghế A - Trái'!$G$4:$H$6 -> SẢN XUẤT HÀNG LOẠT | I4: =$C$3 -> 110
A5: ='Chân ghế A - Trái'!$A$5:$B$5 -> MÃ BẢN VẼ: | C5: KM-36127.108-19
A6: ='Chân ghế A - Trái'!$A$6:$B$6 -> CHÚ Ý:
A8: OPERATION # 01- DẬP CẮT LÁP
A9: =$A$9 -> Part Number ( Mã bản vẽ ) | B9: KM-37008-19
A10: =$A$10 -> Ngày/Tháng/Năm | L10: ='Chân ghế A - Trái'!$L$10:$M$10 -> Thời gian Setup ( phút )
A11: =$A$11 -> SETUP | L11: 30
A12: =$A$12 -> Nhân viên Setup
A13: =$A$13 -> Ngày/Tháng/Năm | J13: Tổng cộng | L13: ='Chân ghế A - Trái'!L13 -> Thời gian gia công / sản phẩm (s) | M13: ='Chân ghế A - Trái'!M13 -> Tổng thời gian gia công dự kiến ( giờ )
A14: =$A$14 -> Thời gian gia công | L14: 20 | M14: =$I$4*L14/3600+$L$11/60 -> 1.1111111
A15: =$A$15 -> Hàng đạt:
A16: =$A$16 -> Hàng lỗi:
A17: =$A$17 -> Tổng số lượng sản xuất:
A18: =$A$18 -> Nhân viên SX:
A19: =$A$19 -> Nhân viên QC:
A20: OPERATION # 02- CHẤN
A21: =$A$9 -> Part Number ( Mã bản vẽ ) | B21: KM-36127.108-19
A22: =$A$10 -> Ngày/Tháng/Năm | L22: ='Chân ghế A - Trái'!$L$10:$M$10 -> Thời gian Setup ( phút )
A23: =$A$11 -> SETUP | L23: 30
A24: =$A$12 -> Nhân viên Setup
A25: =$A$13 -> Ngày/Tháng/Năm | J25: Tổng cộng | L25: ='Chân ghế A - Trái'!$L$37 -> Thời gian gia công / sản phẩm (s) | M25: ='Chân ghế A - Trái'!$M$37 -> Tổng thời gian gia công dự kiến ( giờ )
A26: =$A$14 -> Thời gian gia công | L26: 40 | M26: =$I$4*L26/3600+L23/60 -> 1.7222222
A27: =$A$15 -> Hàng đạt:
A28: =$A$16 -> Hàng lỗi:
A29: =$A$17 -> Tổng số lượng sản xuất:
A30: =$A$18 -> Nhân viên SX:
A31: =$A$19 -> Nhân viên QC:
A33: XÁC NHẬN CỦA GIÁM ĐỐC SẢN XUẤT

Sheet Thanh láp nối khung ghế
C1: ='Chân ghế A - Trái'!$C$1:$I$1 -> GO ROUTER # LỘ TRÌNH SẢN XUẤT | J1: ='Chân ghế A - Trái'!J1:M1 -> Mã số: SX-1/BM1 Lần ban hành: 1 Ngày BH: 7/9/2026
A2: ='Chân ghế A - Trái'!$A$2:$B$2 -> PO NUMBER: | C2: ='Chân ghế A - Trái'!C2:F2 -> 6126 | G2: ='Chân ghế A - Trái'!$G$2:$H$3 -> LOẠI ĐƠN HÀNG | I2: ='Chân ghế A - Trái'!$I$2:$I$3 -> SỐ LƯỢNG | J2: HÌNH ẢNH
A3: ='Chân ghế A - Trái'!A3:B3 -> QTY: | C3: ='Chân ghế A - Trái'!C3:F3 -> 110
A4: ='Chân ghế A - Trái'!$A$4:$B$4 -> TÊN BẢN VẼ: | C4: Thanh láp nối khung ghế | G4: ='Chân ghế A - Trái'!$G$4:$H$6 -> SẢN XUẤT HÀNG LOẠT | I4: =$C$3*2 -> 220
A5: ='Chân ghế A - Trái'!$A$5:$B$5 -> MÃ BẢN VẼ: | C5: KM-37808-20
A6: ='Chân ghế A - Trái'!$A$6:$B$6 -> CHÚ Ý:
A8: OPERATION # 01- DẬP CẮT LÁP
A9: =$A$9 -> Part Number ( Mã bản vẽ ) | B9: KM-37808-20
A10: =$A$10 -> Ngày/Tháng/Năm | L10: ='Chân ghế A - Trái'!$L$10:$M$10 -> Thời gian Setup ( phút )
A11: =$A$11 -> SETUP | L11: 15
A12: =$A$12 -> Nhân viên Setup
A13: =$A$13 -> Ngày/Tháng/Năm | J13: Tổng cộng | L13: ='Chân ghế A - Trái'!L13 -> Thời gian gia công / sản phẩm (s) | M13: ='Chân ghế A - Trái'!M13 -> Tổng thời gian gia công dự kiến ( giờ )
A14: =$A$14 -> Thời gian gia công | L14: 15 | M14: =$I$4*L14/3600+$L$11/60 -> 1.1666667
A15: =$A$15 -> Hàng đạt:
A16: =$A$16 -> Hàng lỗi:
A17: =$A$17 -> Tổng số lượng sản xuất:
A18: =$A$18 -> Nhân viên SX:
A19: =$A$19 -> Nhân viên QC:
A21: XÁC NHẬN CỦA GIÁM ĐỐC SẢN XUẤT

Sheet Thanh láp chéo phi 8 mm
C1: ='Chân ghế A - Trái'!$C$1:$I$1 -> GO ROUTER # LỘ TRÌNH SẢN XUẤT | J1: ='Chân ghế A - Trái'!J1:M1 -> Mã số: SX-1/BM1 Lần ban hành: 1 Ngày BH: 7/9/2026
A2: ='Chân ghế A - Trái'!$A$2:$B$2 -> PO NUMBER: | C2: ='Chân ghế A - Trái'!C2:F2 -> 6126 | G2: ='Chân ghế A - Trái'!$G$2:$H$3 -> LOẠI ĐƠN HÀNG | I2: ='Chân ghế A - Trái'!$I$2:$I$3 -> SỐ LƯỢNG | J2: HÌNH ẢNH
A3: ='Chân ghế A - Trái'!A3:B3 -> QTY: | C3: ='Chân ghế A - Trái'!C3:F3 -> 110
A4: ='Chân ghế A - Trái'!$A$4:$B$4 -> TÊN BẢN VẼ: | C4: Thanh láp chéo phi 8 mm | G4: ='Chân ghế A - Trái'!$G$4:$H$6 -> SẢN XUẤT HÀNG LOẠT | I4: =$C$3*2 -> 220
A5: ='Chân ghế A - Trái'!$A$5:$B$5 -> MÃ BẢN VẼ: | C5: KM-504.6408-21
A6: ='Chân ghế A - Trái'!$A$6:$B$6 -> CHÚ Ý:
A8: OPERATION # 01- DẬP CẮT LÁP
A9: =$A$9 -> Part Number ( Mã bản vẽ ) | B9: KM-504.6408-21
A10: =$A$10 -> Ngày/Tháng/Năm | L10: ='Chân ghế A - Trái'!$L$10:$M$10 -> Thời gian Setup ( phút )
A11: =$A$11 -> SETUP | L11: 15
A12: =$A$12 -> Nhân viên Setup
A13: =$A$13 -> Ngày/Tháng/Năm | J13: Tổng cộng | L13: ='Chân ghế A - Trái'!L13 -> Thời gian gia công / sản phẩm (s) | M13: ='Chân ghế A - Trái'!M13 -> Tổng thời gian gia công dự kiến ( giờ )
A14: =$A$14 -> Thời gian gia công | L14: 15 | M14: =$I$4*L14/3600+L11/60 -> 1.1666667
A15: =$A$15 -> Hàng đạt:
A16: =$A$16 -> Hàng lỗi:
A17: =$A$17 -> Tổng số lượng sản xuất:
A18: =$A$18 -> Nhân viên SX:
A19: =$A$19 -> Nhân viên QC:
A21: XÁC NHẬN CỦA GIÁM ĐỐC SẢN XUẤT

Sheet Chốt tay ghế
C1: ='Chân ghế A - Trái'!$C$1:$I$1 -> GO ROUTER # LỘ TRÌNH SẢN XUẤT | J1: ='Chân ghế A - Trái'!J1:M1 -> Mã số: SX-1/BM1 Lần ban hành: 1 Ngày BH: 7/9/2026
A2: ='Chân ghế A - Trái'!$A$2:$B$2 -> PO NUMBER: | C2: ='Chân ghế A - Trái'!C2:F2 -> 6126 | G2: ='Chân ghế A - Trái'!$G$2:$H$3 -> LOẠI ĐƠN HÀNG | I2: ='Chân ghế A - Trái'!$I$2:$I$3 -> SỐ LƯỢNG | J2: HÌNH ẢNH
A3: ='Chân ghế A - Trái'!A3:B3 -> QTY: | C3: ='Chân ghế A - Trái'!C3:F3 -> 110
A4: ='Chân ghế A - Trái'!$A$4:$B$4 -> TÊN BẢN VẼ: | C4: Chốt tay ghế | G4: ='Chân ghế A - Trái'!$G$4:$H$6 -> SẢN XUẤT HÀNG LOẠT | I4: =$C$3*2 -> 220
A5: ='Chân ghế A - Trái'!$A$5:$B$5 -> MÃ BẢN VẼ: | C5: KM-3919.87.9-22
A6: ='Chân ghế A - Trái'!$A$6:$B$6 -> CHÚ Ý:
A8: OPERATION # 01- TIỆN BƯỚC 1
A9: =$A$21 -> Part Number ( Mã bản vẽ ) | B9: KM-3919.87.9-22
A10: =$A$22 -> Ngày/Tháng/Năm | L10: ='Chân ghế A - Trái'!$L$10:$M$10 -> Thời gian Setup ( phút )
A11: =$A$23 -> SETUP | L11: 90
A12: =$A$24 -> Nhân viên Setup
A13: =$A$25 -> Ngày/Tháng/Năm | J13: Tổng cộng | L13: ='Chân ghế A - Trái'!$L$13 -> Thời gian gia công / sản phẩm (s) | M13: ='Chân ghế A - Trái'!$M$13 -> Tổng thời gian gia công dự kiến ( giờ )
A14: =$A$26 -> Thời gian gia công | L14: 180 | M14: =$I$4*L14/3600+L11/60 -> 12.5
A15: =$A$27 -> Hàng đạt:
A16: =$A$28 -> Hàng lỗi:
A17: =$A$29 -> Tổng số lượng sản xuất:
A18: =$A$30 -> Nhân viên SX:
A19: =$A$31 -> Nhân viên QC:
A20: OPERATION # 01- TIỆN BƯỚC 2
A21: =$A$21 -> Part Number ( Mã bản vẽ ) | B21: KM-3919.87.9-22
A22: =$A$22 -> Ngày/Tháng/Năm | L22: ='Chân ghế A - Trái'!$L$10:$M$10 -> Thời gian Setup ( phút )
A23: =$A$23 -> SETUP | L23: 60
A24: =$A$24 -> Nhân viên Setup
A25: =$A$25 -> Ngày/Tháng/Năm | J25: Tổng cộng | L25: ='Chân ghế A - Trái'!$L$13 -> Thời gian gia công / sản phẩm (s) | M25: ='Chân ghế A - Trái'!$M$13 -> Tổng thời gian gia công dự kiến ( giờ )
A26: =$A$26 -> Thời gian gia công | L26: 90 | M26: =$I$4*L26/3600+L23/60 -> 6.5
A27: =$A$27 -> Hàng đạt:
A28: =$A$28 -> Hàng lỗi:
A29: =$A$29 -> Tổng số lượng sản xuất:
A30: =$A$30 -> Nhân viên SX:
A31: =$A$31 -> Nhân viên QC:
A33: XÁC NHẬN CỦA GIÁM ĐỐC SẢN XUẤT

Sheet Sơ mi ( tay ghế )
C1: ='Chân ghế A - Trái'!$C$1:$I$1 -> GO ROUTER # LỘ TRÌNH SẢN XUẤT | J1: ='Chân ghế A - Trái'!J1:M1 -> Mã số: SX-1/BM1 Lần ban hành: 1 Ngày BH: 7/9/2026
A2: ='Chân ghế A - Trái'!$A$2:$B$2 -> PO NUMBER: | C2: ='Chân ghế A - Trái'!C2:F2 -> 6126 | G2: ='Chân ghế A - Trái'!$G$2:$H$3 -> LOẠI ĐƠN HÀNG | I2: ='Chân ghế A - Trái'!$I$2:$I$3 -> SỐ LƯỢNG | J2: HÌNH ẢNH
A3: ='Chân ghế A - Trái'!A3:B3 -> QTY: | C3: ='Chân ghế A - Trái'!C3:F3 -> 110
A4: ='Chân ghế A - Trái'!$A$4:$B$4 -> TÊN BẢN VẼ: | C4: Sơ mi ( tay ghế ) | G4: ='Chân ghế A - Trái'!$G$4:$H$6 -> SẢN XUẤT HÀNG LOẠT | I4: =$C$3*2 -> 220
A5: ='Chân ghế A - Trái'!$A$5:$B$5 -> MÃ BẢN VẼ: | C5: KM-2015.9-23
A6: ='Chân ghế A - Trái'!$A$6:$B$6 -> CHÚ Ý:
A8: OPERATION # 01- TIỆN
A9: =$A$9 -> Part Number ( Mã bản vẽ ) | B9: KM-2015.9-23
A10: =$A$10 -> Ngày/Tháng/Năm | L10: ='Chân ghế A - Trái'!$L$10:$M$10 -> Thời gian Setup ( phút )
A11: =$A$11 -> SETUP | L11: 30
A12: =$A$12 -> Nhân viên Setup
A13: =$A$13 -> Ngày/Tháng/Năm | J13: Tổng cộng | L13: ='Chân ghế A - Trái'!$L$13 -> Thời gian gia công / sản phẩm (s) | M13: ='Chân ghế A - Trái'!$M$13 -> Tổng thời gian gia công dự kiến ( giờ )
A14: =$A$14 -> Thời gian gia công | L14: 10 | M14: =$I$4*L14/3600+L11/60 -> 1.1111111
A15: =$A$15 -> Hàng đạt:
A16: =$A$16 -> Hàng lỗi:
A17: =$A$17 -> Tổng số lượng sản xuất:
A18: =$A$18 -> Nhân viên SX:
A19: =$A$19 -> Nhân viên QC:
A20: OPERATION # 02- LÀM NGUỘI
A21: =$A$9 -> Part Number ( Mã bản vẽ )
A22: =$A$10 -> Ngày/Tháng/Năm | L22: ='Chân ghế A - Trái'!$L$10:$M$10 -> Thời gian Setup ( phút )
A23: =$A$11 -> SETUP | L23: 0
A24: =$A$12 -> Nhân viên Setup
